Workbook

Sheet Agosto 2026
B1: Finanzas personales | D1: Agosto 2026 | M1: Tasa del mes | N1: ="1 USD = "&FIXED($T$3,2)&" DOP"
B2: Mes nuevo: usa "Cerrar mes" en la página y descarga el Excel, o duplica esta hoja (clic derecho en la pestaña → Mover o copiar → Crear una copia). | T2: Cálculos
T3: =IFERROR(SUMPRODUCT(Env_2026_08[USD],Env_2026_08[Tasa])/SUM(Env_2026_08[USD]),Config!$C$4)
B4: DINERO TOTAL | G4: PRESUPUESTO USADO | J4: =UPPER($D$1) | T4: =SUMIFS(Fijos_2026_08[DOP],Fijos_2026_08[Pagado],"Sí")
B5: =C8*$T$3+C9 | J5: =FIXED(100*$T$8/MAX(1,O6),1)&"% del presupuesto usado" | T5: =SUM(Tx_2026_08[DOP])
B6: =C8+C9/$T$3 | G6: ■ Fijos pagados | I6: =$T$4 | J6: Presupuesto planeado | O6: 70000 | T6: =SUMIFS(Fijos_2026_08[DOP],Fijos_2026_08[Pagado],"No")
T7: =MAX(0,O6-T4-T5-T6)
B8: Cuenta USA | C8: 3900 | D8: USD | G8: ■ Transacciones | I8: =$T$5 | J8: Usado hasta hoy | O8: =$T$8 | T8: =T4+T5
B9: Cuenta RD | C9: 78200 | D9: DOP | G9: ■ Fijos pendientes | I9: =$T$6 | J9: Disponible | O9: =O6-O8 | T9: =FIXED(T8,0)
B10: Ingreso del mes | C10: 5800 | D10: USD | G10: ■ Libre | I10: =$T$7 | J10: Disponible tras fijos pendientes | O10: =O9-$T$6 | T10: ="de "&FIXED(O6,0)&" DOP"
B11: Ingreso − usado | C11: =C10*$T$3-$T$8 | J11: Usado en USD | O11: =$T$8/$T$3
B14: Gastos mensuales | H14: =COUNTIFS(Fijos_2026_08[Pagado],"Sí")&" de "&COUNTA(Fijos_2026_08[Concepto])&" pagados · total "&FIXED(SUM(Fijos_2026_08[DOP]),2)&" DOP" | M14: Por categoría | Q14: DOP
B15: Pagado | C15: Concepto | D15: Día de cobro | E15: Monto | F15: Moneda | G15: DOP | H15: USD | M15: Gastos fijos | O15: =Q15 | Q15: =$T$4
B16: Sí | C16: Luz | E16: 1290.4 | F16: DOP | G16: =IF(Fijos_2026_08[[#This Row],[Monto]]="","",IF(Fijos_2026_08[[#This Row],[Moneda]]="USD",Fijos_2026_08[[#This Row],[Monto]]*$T$3,Fijos_2026_08[[#This Row],[Monto]])) | H16: =IF(Fijos_2026_08[[#This Row],[DOP]]="","",Fijos_2026_08[[#This Row],[DOP]]/$T$3) | M16: Comida | O16: =Q16 | Q16: =SUMIFS(Tx_2026_08[DOP],Tx_2026_08[Categoría],M16)
B17: Sí | C17: Internet | E17: 2699 | F17: DOP | G17: =IF(Fijos_2026_08[[#This Row],[Monto]]="","",IF(Fijos_2026_08[[#This Row],[Moneda]]="USD",Fijos_2026_08[[#This Row],[Monto]]*$T$3,Fijos_2026_08[[#This Row],[Monto]])) | H17: =IF(Fijos_2026_08[[#This Row],[DOP]]="","",Fijos_2026_08[[#This Row],[DOP]]/$T$3) | M17: Supermercado | O17: =Q17 | Q17: =SUMIFS(Tx_2026_08[DOP],Tx_2026_08[Categoría],M17)
B18: Sí | C18: Seguro médico | E18: 5640 | F18: DOP | G18: =IF(Fijos_2026_08[[#This Row],[Monto]]="","",IF(Fijos_2026_08[[#This Row],[Moneda]]="USD",Fijos_2026_08[[#This Row],[Monto]]*$T$3,Fijos_2026_08[[#This Row],[Monto]])) | H18: =IF(Fijos_2026_08[[#This Row],[DOP]]="","",Fijos_2026_08[[#This Row],[DOP]]/$T$3) | M18: Transporte | O18: =Q18 | Q18: =SUMIFS(Tx_2026_08[DOP],Tx_2026_08[Categoría],M18)
B19: Sí | C19: Pago nevera | E19: 15000 | F19: DOP | G19: =IF(Fijos_2026_08[[#This Row],[Monto]]="","",IF(Fijos_2026_08[[#This Row],[Moneda]]="USD",Fijos_2026_08[[#This Row],[Monto]]*$T$3,Fijos_2026_08[[#This Row],[Monto]])) | H19: =IF(Fijos_2026_08[[#This Row],[DOP]]="","",Fijos_2026_08[[#This Row],[DOP]]/$T$3) | M19: Entretenimiento | O19: =Q19 | Q19: =SUMIFS(Tx_2026_08[DOP],Tx_2026_08[Categoría],M19)
B20: Sí | C20: Claude | D20: 5 | E20: 106 | F20: USD | G20: =IF(Fijos_2026_08[[#This Row],[Monto]]="","",IF(Fijos_2026_08[[#This Row],[Moneda]]="USD",Fijos_2026_08[[#This Row],[Monto]]*$T$3,Fijos_2026_08[[#This Row],[Monto]])) | H20: =IF(Fijos_2026_08[[#This Row],[DOP]]="","",Fijos_2026_08[[#This Row],[DOP]]/$T$3) | M20: Salud | O20: =Q20 | Q20: =SUMIFS(Tx_2026_08[DOP],Tx_2026_08[Categoría],M20)
B21: Sí | C21: Google One | D21: 16 | E21: 121.56 | F21: DOP | G21: =IF(Fijos_2026_08[[#This Row],[Monto]]="","",IF(Fijos_2026_08[[#This Row],[Moneda]]="USD",Fijos_2026_08[[#This Row],[Monto]]*$T$3,Fijos_2026_08[[#This Row],[Monto]])) | H21: =IF(Fijos_2026_08[[#This Row],[DOP]]="","",Fijos_2026_08[[#This Row],[DOP]]/$T$3) | M21: Ropa | O21: =Q21 | Q21: =SUMIFS(Tx_2026_08[DOP],Tx_2026_08[Categoría],M21)
B22: Sí | C22: iCloud+ | D22: 17 | E22: 604 | F22: DOP | G22: =IF(Fijos_2026_08[[#This Row],[Monto]]="","",IF(Fijos_2026_08[[#This Row],[Moneda]]="USD",Fijos_2026_08[[#This Row],[Monto]]*$T$3,Fijos_2026_08[[#This Row],[Monto]])) | H22: =IF(Fijos_2026_08[[#This Row],[DOP]]="","",Fijos_2026_08[[#This Row],[DOP]]/$T$3) | M22: Hogar | O22: =Q22 | Q22: =SUMIFS(Tx_2026_08[DOP],Tx_2026_08[Categoría],M22)
B23: Sí | C23: Cluely | E23: 308 | F23: DOP | G23: =IF(Fijos_2026_08[[#This Row],[Monto]]="","",IF(Fijos_2026_08[[#This Row],[Moneda]]="USD",Fijos_2026_08[[#This Row],[Monto]]*$T$3,Fijos_2026_08[[#This Row],[Monto]])) | H23: =IF(Fijos_2026_08[[#This Row],[DOP]]="","",Fijos_2026_08[[#This Row],[DOP]]/$T$3) | M23: Suscripciones | O23: =Q23 | Q23: =SUMIFS(Tx_2026_08[DOP],Tx_2026_08[Categoría],M23)
B24: Sí | C24: Smartfit | D24: 17 | E24: 1550 | F24: DOP | G24: =IF(Fijos_2026_08[[#This Row],[Monto]]="","",IF(Fijos_2026_08[[#This Row],[Moneda]]="USD",Fijos_2026_08[[#This Row],[Monto]]*$T$3,Fijos_2026_08[[#This Row],[Monto]])) | H24: =IF(Fijos_2026_08[[#This Row],[DOP]]="","",Fijos_2026_08[[#This Row],[DOP]]/$T$3) | M24: Educación | O24: =Q24 | Q24: =SUMIFS(Tx_2026_08[DOP],Tx_2026_08[Categoría],M24)
B25: Sí | C25: Netflix | E25: 1137.3 | F25: DOP | G25: =IF(Fijos_2026_08[[#This Row],[Monto]]="","",IF(Fijos_2026_08[[#This Row],[Moneda]]="USD",Fijos_2026_08[[#This Row],[Monto]]*$T$3,Fijos_2026_08[[#This Row],[Monto]])) | H25: =IF(Fijos_2026_08[[#This Row],[DOP]]="","",Fijos_2026_08[[#This Row],[DOP]]/$T$3) | M25: Viajes | O25: =Q25 | Q25: =SUMIFS(Tx_2026_08[DOP],Tx_2026_08[Categoría],M25)
B26: Sí | C26: Unicaribe | E26: 7400 | F26: DOP | G26: =IF(Fijos_2026_08[[#This Row],[Monto]]="","",IF(Fijos_2026_08[[#This Row],[Moneda]]="USD",Fijos_2026_08[[#This Row],[Monto]]*$T$3,Fijos_2026_08[[#This Row],[Monto]])) | H26: =IF(Fijos_2026_08[[#This Row],[DOP]]="","",Fijos_2026_08[[#This Row],[DOP]]/$T$3)
G27: =IF(Fijos_2026_08[[#This Row],[Monto]]="","",IF(Fijos_2026_08[[#This Row],[Moneda]]="USD",Fijos_2026_08[[#This Row],[Monto]]*$T$3,Fijos_2026_08[[#This Row],[Monto]])) | H27: =IF(Fijos_2026_08[[#This Row],[DOP]]="","",Fijos_2026_08[[#This Row],[DOP]]/$T$3)
G28: =IF(Fijos_2026_08[[#This Row],[Monto]]="","",IF(Fijos_2026_08[[#This Row],[Moneda]]="USD",Fijos_2026_08[[#This Row],[Monto]]*$T$3,Fijos_2026_08[[#This Row],[Monto]])) | H28: =IF(Fijos_2026_08[[#This Row],[DOP]]="","",Fijos_2026_08[[#This Row],[DOP]]/$T$3) | M28: Envíos USD → DOP | O28: ="Promedio "&FIXED($T$3,2)
G29: =IF(Fijos_2026_08[[#This Row],[Monto]]="","",IF(Fijos_2026_08[[#This Row],[Moneda]]="USD",Fijos_2026_08[[#This Row],[Monto]]*$T$3,Fijos_2026_08[[#This Row],[Monto]])) | H29: =IF(Fijos_2026_08[[#This Row],[DOP]]="","",Fijos_2026_08[[#This Row],[DOP]]/$T$3) | M29: Fecha | N29: Vía | O29: USD | P29: Tasa | Q29: DOP
G30: =IF(Fijos_2026_08[[#This Row],[Monto]]="","",IF(Fijos_2026_08[[#This Row],[Moneda]]="USD",Fijos_2026_08[[#This Row],[Monto]]*$T$3,Fijos_2026_08[[#This Row],[Monto]])) | H30: =IF(Fijos_2026_08[[#This Row],[DOP]]="","",Fijos_2026_08[[#This Row],[DOP]]/$T$3) | M30: 46237 | N30: Remitly | O30: 1500 | P30: 58.4 | Q30: =IF(Env_2026_08[[#This Row],[USD]]="","",Env_2026_08[[#This Row],[USD]]*Env_2026_08[[#This Row],[Tasa]])
M31: 46252 | N31: PayPal | O31: 300 | P31: 57.1 | Q31: =IF(Env_2026_08[[#This Row],[USD]]="","",Env_2026_08[[#This Row],[USD]]*Env_2026_08[[#This Row],[Tasa]])
Q32: =IF(Env_2026_08[[#This Row],[USD]]="","",Env_2026_08[[#This Row],[USD]]*Env_2026_08[[#This Row],[Tasa]])
Q33: =IF(Env_2026_08[[#This Row],[USD]]="","",Env_2026_08[[#This Row],[USD]]*Env_2026_08[[#This Row],[Tasa]])
Q34: =IF(Env_2026_08[[#This Row],[USD]]="","",Env_2026_08[[#This Row],[USD]]*Env_2026_08[[#This Row],[Tasa]])
B37: Historial de transacciones | H37: =COUNT(Tx_2026_08[Monto])&" transacciones · total "&FIXED($T$5,2)&" DOP"
B38: Fecha | C38: Descripción | D38: Lugar | E38: Categoría | F38: Método | G38: Monto | H38: Moneda | I38: DOP | J38: USD | K38: Notas
B39: 46236 | C39: Compra semanal | D39: Supermercado Nacional | E39: Supermercado | F39: Tarjeta | G39: 5230 | H39: DOP | I39: =IF(Tx_2026_08[[#This Row],[Monto]]="","",IF(Tx_2026_08[[#This Row],[Moneda]]="USD",Tx_2026_08[[#This Row],[Monto]]*$T$3,Tx_2026_08[[#This Row],[Monto]])) | J39: =IF(Tx_2026_08[[#This Row],[DOP]]="","",Tx_2026_08[[#This Row],[DOP]]/$T$3)
B40: 46238 | C40: Uber | D40: Uber | E40: Transporte | F40: Tarjeta | G40: 410 | H40: DOP | I40: =IF(Tx_2026_08[[#This Row],[Monto]]="","",IF(Tx_2026_08[[#This Row],[Moneda]]="USD",Tx_2026_08[[#This Row],[Monto]]*$T$3,Tx_2026_08[[#This Row],[Monto]])) | J40: =IF(Tx_2026_08[[#This Row],[DOP]]="","",Tx_2026_08[[#This Row],[DOP]]/$T$3)
B41: 46240 | C41: Almuerzo | D41: Adrian Tropical | E41: Comida | F41: Tarjeta | G41: 1280 | H41: DOP | I41: =IF(Tx_2026_08[[#This Row],[Monto]]="","",IF(Tx_2026_08[[#This Row],[Moneda]]="USD",Tx_2026_08[[#This Row],[Monto]]*$T$3,Tx_2026_08[[#This Row],[Monto]])) | J41: =IF(Tx_2026_08[[#This Row],[DOP]]="","",Tx_2026_08[[#This Row],[DOP]]/$T$3)
B42: 46243 | C42: Gasolina | D42: Texaco Churchill | E42: Transporte | F42: Tarjeta | G42: 2200 | H42: DOP | I42: =IF(Tx_2026_08[[#This Row],[Monto]]="","",IF(Tx_2026_08[[#This Row],[Moneda]]="USD",Tx_2026_08[[#This Row],[Monto]]*$T$3,Tx_2026_08[[#This Row],[Monto]])) | J42: =IF(Tx_2026_08[[#This Row],[DOP]]="","",Tx_2026_08[[#This Row],[DOP]]/$T$3)
B43: 46246 | C43: Concierto | D43: Teatro Nacional | E43: Entretenimiento | F43: App del banco | G43: 2500 | H43: DOP | I43: =IF(Tx_2026_08[[#This Row],[Monto]]="","",IF(Tx_2026_08[[#This Row],[Moneda]]="USD",Tx_2026_08[[#This Row],[Monto]]*$T$3,Tx_2026_08[[#This Row],[Monto]])) | J43: =IF(Tx_2026_08[[#This Row],[DOP]]="","",Tx_2026_08[[#This Row],[DOP]]/$T$3)
B44: 46249 | C44: Compra semanal | D44: Jumbo | E44: Supermercado | F44: Tarjeta | G44: 4680 | H44: DOP | I44: =IF(Tx_2026_08[[#This Row],[Monto]]="","",IF(Tx_2026_08[[#This Row],[Moneda]]="USD",Tx_2026_08[[#This Row],[Monto]]*$T$3,Tx_2026_08[[#This Row],[Monto]])) | J44: =IF(Tx_2026_08[[#This Row],[DOP]]="","",Tx_2026_08[[#This Row],[DOP]]/$T$3)
...

Sheet Septiembre 2026
B1: Finanzas personales | D1: Septiembre 2026 | M1: Tasa del mes | N1: ="1 USD = "&FIXED($T$3,2)&" DOP"
B2: Mes nuevo: usa "Cerrar mes" en la página y descarga el Excel, o duplica esta hoja (clic derecho en la pestaña → Mover o copiar → Crear una copia). | T2: Cálculos
T3: =IFERROR(SUMPRODUCT(Env_2026_09[USD],Env_2026_09[Tasa])/SUM(Env_2026_09[USD]),Config!$C$4)
B4: DINERO TOTAL | G4: PRESUPUESTO USADO | J4: =UPPER($D$1) | T4: =SUMIFS(Fijos_2026_09[DOP],Fijos_2026_09[Pagado],"Sí")
B5: =C8*$T$3+C9 | J5: =FIXED(100*$T$8/MAX(1,O6),1)&"% del presupuesto usado" | T5: =SUM(Tx_2026_09[DOP])
B6: =C8+C9/$T$3 | G6: ■ Fijos pagados | I6: =$T$4 | J6: Presupuesto planeado | O6: 70000 | T6: =SUMIFS(Fijos_2026_09[DOP],Fijos_2026_09[Pagado],"No")
T7: =MAX(0,O6-T4-T5-T6)
B8: Cuenta USA | C8: 4100 | D8: USD | G8: ■ Transacciones | I8: =$T$5 | J8: Usado hasta hoy | O8: =$T$8 | T8: =T4+T5
B9: Cuenta RD | C9: 81500 | D9: DOP | G9: ■ Fijos pendientes | I9: =$T$6 | J9: Disponible | O9: =O6-O8 | T9: =FIXED(T8,0)
B10: Ingreso del mes | C10: 5800 | D10: USD | G10: ■ Libre | I10: =$T$7 | J10: Disponible tras fijos pendientes | O10: =O9-$T$6 | T10: ="de "&FIXED(O6,0)&" DOP"
B11: Ingreso − usado | C11: =C10*$T$3-$T$8 | J11: Usado en USD | O11: =$T$8/$T$3
B14: Gastos mensuales | H14: =COUNTIFS(Fijos_2026_09[Pagado],"Sí")&" de "&COUNTA(Fijos_2026_09[Concepto])&" pagados · total "&FIXED(SUM(Fijos_2026_09[DOP]),2)&" DOP" | M14: Por categoría | Q14: DOP
B15: Pagado | C15: Concepto | D15: Día de cobro | E15: Monto | F15: Moneda | G15: DOP | H15: USD | M15: Gastos fijos | O15: =Q15 | Q15: =$T$4
B16: Sí | C16: Luz | E16: 1412.8 | F16: DOP | G16: =IF(Fijos_2026_09[[#This Row],[Monto]]="","",IF(Fijos_2026_09[[#This Row],[Moneda]]="USD",Fijos_2026_09[[#This Row],[Monto]]*$T$3,Fijos_2026_09[[#This Row],[Monto]])) | H16: =IF(Fijos_2026_09[[#This Row],[DOP]]="","",Fijos_2026_09[[#This Row],[DOP]]/$T$3) | M16: Comida | O16: =Q16 | Q16: =SUMIFS(Tx_2026_09[DOP],Tx_2026_09[Categoría],M16)
B17: Sí | C17: Internet | E17: 2699 | F17: DOP | G17: =IF(Fijos_2026_09[[#This Row],[Monto]]="","",IF(Fijos_2026_09[[#This Row],[Moneda]]="USD",Fijos_2026_09[[#This Row],[Monto]]*$T$3,Fijos_2026_09[[#This Row],[Monto]])) | H17: =IF(Fijos_2026_09[[#This Row],[DOP]]="","",Fijos_2026_09[[#This Row],[DOP]]/$T$3) | M17: Supermercado | O17: =Q17 | Q17: =SUMIFS(Tx_2026_09[DOP],Tx_2026_09[Categoría],M17)
B18: Sí | C18: Seguro médico | E18: 5640 | F18: DOP | G18: =IF(Fijos_2026_09[[#This Row],[Monto]]="","",IF(Fijos_2026_09[[#This Row],[Moneda]]="USD",Fijos_2026_09[[#This Row],[Monto]]*$T$3,Fijos_2026_09[[#This Row],[Monto]])) | H18: =IF(Fijos_2026_09[[#This Row],[DOP]]="","",Fijos_2026_09[[#This Row],[DOP]]/$T$3) | M18: Transporte | O18: =Q18 | Q18: =SUMIFS(Tx_2026_09[DOP],Tx_2026_09[Categoría],M18)
B19: Sí | C19: Pago nevera | E19: 15000 | F19: DOP | G19: =IF(Fijos_2026_09[[#This Row],[Monto]]="","",IF(Fijos_2026_09[[#This Row],[Moneda]]="USD",Fijos_2026_09[[#This Row],[Monto]]*$T$3,Fijos_2026_09[[#This Row],[Monto]])) | H19: =IF(Fijos_2026_09[[#This Row],[DOP]]="","",Fijos_2026_09[[#This Row],[DOP]]/$T$3) | M19: Entretenimiento | O19: =Q19 | Q19: =SUMIFS(Tx_2026_09[DOP],Tx_2026_09[Categoría],M19)
B20: Sí | C20: Claude | D20: 5 | E20: 106 | F20: USD | G20: =IF(Fijos_2026_09[[#This Row],[Monto]]="","",IF(Fijos_2026_09[[#This Row],[Moneda]]="USD",Fijos_2026_09[[#This Row],[Monto]]*$T$3,Fijos_2026_09[[#This Row],[Monto]])) | H20: =IF(Fijos_2026_09[[#This Row],[DOP]]="","",Fijos_2026_09[[#This Row],[DOP]]/$T$3) | M20: Salud | O20: =Q20 | Q20: =SUMIFS(Tx_2026_09[DOP],Tx_2026_09[Categoría],M20)
B21: Sí | C21: Google One | D21: 16 | E21: 121.56 | F21: DOP | G21: =IF(Fijos_2026_09[[#This Row],[Monto]]="","",IF(Fijos_2026_09[[#This Row],[Moneda]]="USD",Fijos_2026_09[[#This Row],[Monto]]*$T$3,Fijos_2026_09[[#This Row],[Monto]])) | H21: =IF(Fijos_2026_09[[#This Row],[DOP]]="","",Fijos_2026_09[[#This Row],[DOP]]/$T$3) | M21: Ropa | O21: =Q21 | Q21: =SUMIFS(Tx_2026_09[DOP],Tx_2026_09[Categoría],M21)
B22: Sí | C22: iCloud+ | D22: 17 | E22: 604 | F22: DOP | G22: =IF(Fijos_2026_09[[#This Row],[Monto]]="","",IF(Fijos_2026_09[[#This Row],[Moneda]]="USD",Fijos_2026_09[[#This Row],[Monto]]*$T$3,Fijos_2026_09[[#This Row],[Monto]])) | H22: =IF(Fijos_2026_09[[#This Row],[DOP]]="","",Fijos_2026_09[[#This Row],[DOP]]/$T$3) | M22: Hogar | O22: =Q22 | Q22: =SUMIFS(Tx_2026_09[DOP],Tx_2026_09[Categoría],M22)
B23: Sí | C23: Cluely | E23: 308 | F23: DOP | G23: =IF(Fijos_2026_09[[#This Row],[Monto]]="","",IF(Fijos_2026_09[[#This Row],[Moneda]]="USD",Fijos_2026_09[[#This Row],[Monto]]*$T$3,Fijos_2026_09[[#This Row],[Monto]])) | H23: =IF(Fijos_2026_09[[#This Row],[DOP]]="","",Fijos_2026_09[[#This Row],[DOP]]/$T$3) | M23: Suscripciones | O23: =Q23 | Q23: =SUMIFS(Tx_2026_09[DOP],Tx_2026_09[Categoría],M23)
B24: Sí | C24: Smartfit | D24: 17 | E24: 1550 | F24: DOP | G24: =IF(Fijos_2026_09[[#This Row],[Monto]]="","",IF(Fijos_2026_09[[#This Row],[Moneda]]="USD",Fijos_2026_09[[#This Row],[Monto]]*$T$3,Fijos_2026_09[[#This Row],[Monto]])) | H24: =IF(Fijos_2026_09[[#This Row],[DOP]]="","",Fijos_2026_09[[#This Row],[DOP]]/$T$3) | M24: Educación | O24: =Q24 | Q24: =SUMIFS(Tx_2026_09[DOP],Tx_2026_09[Categoría],M24)
B25: Sí | C25: Netflix | E25: 1137.3 | F25: DOP | G25: =IF(Fijos_2026_09[[#This Row],[Monto]]="","",IF(Fijos_2026_09[[#This Row],[Moneda]]="USD",Fijos_2026_09[[#This Row],[Monto]]*$T$3,Fijos_2026_09[[#This Row],[Monto]])) | H25: =IF(Fijos_2026_09[[#This Row],[DOP]]="","",Fijos_2026_09[[#This Row],[DOP]]/$T$3) | M25: Viajes | O25: =Q25 | Q25: =SUMIFS(Tx_2026_09[DOP],Tx_2026_09[Categoría],M25)
B26: Sí | C26: Unicaribe | E26: 7400 | F26: DOP | G26: =IF(Fijos_2026_09[[#This Row],[Monto]]="","",IF(Fijos_2026_09[[#This Row],[Moneda]]="USD",Fijos_2026_09[[#This Row],[Monto]]*$T$3,Fijos_2026_09[[#This Row],[Monto]])) | H26: =IF(Fijos_2026_09[[#This Row],[DOP]]="","",Fijos_2026_09[[#This Row],[DOP]]/$T$3)
G27: =IF(Fijos_2026_09[[#This Row],[Monto]]="","",IF(Fijos_2026_09[[#This Row],[Moneda]]="USD",Fijos_2026_09[[#This Row],[Monto]]*$T$3,Fijos_2026_09[[#This Row],[Monto]])) | H27: =IF(Fijos_2026_09[[#This Row],[DOP]]="","",Fijos_2026_09[[#This Row],[DOP]]/$T$3)
G28: =IF(Fijos_2026_09[[#This Row],[Monto]]="","",IF(Fijos_2026_09[[#This Row],[Moneda]]="USD",Fijos_2026_09[[#This Row],[Monto]]*$T$3,Fijos_2026_09[[#This Row],[Monto]])) | H28: =IF(Fijos_2026_09[[#This Row],[DOP]]="","",Fijos_2026_09[[#This Row],[DOP]]/$T$3) | M28: Envíos USD → DOP | O28: ="Promedio "&FIXED($T$3,2)
G29: =IF(Fijos_2026_09[[#This Row],[Monto]]="","",IF(Fijos_2026_09[[#This Row],[Moneda]]="USD",Fijos_2026_09[[#This Row],[Monto]]*$T$3,Fijos_2026_09[[#This Row],[Monto]])) | H29: =IF(Fijos_2026_09[[#This Row],[DOP]]="","",Fijos_2026_09[[#This Row],[DOP]]/$T$3) | M29: Fecha | N29: Vía | O29: USD | P29: Tasa | Q29: DOP
G30: =IF(Fijos_2026_09[[#This Row],[Monto]]="","",IF(Fijos_2026_09[[#This Row],[Moneda]]="USD",Fijos_2026_09[[#This Row],[Monto]]*$T$3,Fijos_2026_09[[#This Row],[Monto]])) | H30: =IF(Fijos_2026_09[[#This Row],[DOP]]="","",Fijos_2026_09[[#This Row],[DOP]]/$T$3) | M30: 46267 | N30: Remitly | O30: 1500 | P30: 58.55 | Q30: =IF(Env_2026_09[[#This Row],[USD]]="","",Env_2026_09[[#This Row],[USD]]*Env_2026_09[[#This Row],[Tasa]])
M31: 46282 | N31: Remitly | O31: 800 | P31: 58.62 | Q31: =IF(Env_2026_09[[#This Row],[USD]]="","",Env_2026_09[[#This Row],[USD]]*Env_2026_09[[#This Row],[Tasa]])
Q32: =IF(Env_2026_09[[#This Row],[USD]]="","",Env_2026_09[[#This Row],[USD]]*Env_2026_09[[#This Row],[Tasa]])
Q33: =IF(Env_2026_09[[#This Row],[USD]]="","",Env_2026_09[[#This Row],[USD]]*Env_2026_09[[#This Row],[Tasa]])
Q34: =IF(Env_2026_09[[#This Row],[USD]]="","",Env_2026_09[[#This Row],[USD]]*Env_2026_09[[#This Row],[Tasa]])
B37: Historial de transacciones | H37: =COUNT(Tx_2026_09[Monto])&" transacciones · total "&FIXED($T$5,2)&" DOP"
B38: Fecha | C38: Descripción | D38: Lugar | E38: Categoría | F38: Método | G38: Monto | H38: Moneda | I38: DOP | J38: USD | K38: Notas
B39: 46266 | C39: Compra semanal | D39: Supermercado Bravo | E39: Supermercado | F39: Tarjeta | G39: 4975 | H39: DOP | I39: =IF(Tx_2026_09[[#This Row],[Monto]]="","",IF(Tx_2026_09[[#This Row],[Moneda]]="USD",Tx_2026_09[[#This Row],[Monto]]*$T$3,Tx_2026_09[[#This Row],[Monto]])) | J39: =IF(Tx_2026_09[[#This Row],[DOP]]="","",Tx_2026_09[[#This Row],[DOP]]/$T$3)
B40: 46268 | C40: Libro de contabilidad | D40: Librería Cuesta | E40: Educación | F40: Tarjeta | G40: 1850 | H40: DOP | I40: =IF(Tx_2026_09[[#This Row],[Monto]]="","",IF(Tx_2026_09[[#This Row],[Moneda]]="USD",Tx_2026_09[[#This Row],[Monto]]*$T$3,Tx_2026_09[[#This Row],[Monto]])) | J40: =IF(Tx_2026_09[[#This Row],[DOP]]="","",Tx_2026_09[[#This Row],[DOP]]/$T$3)
B41: 46270 | C41: Uber | D41: Uber | E41: Transporte | F41: Tarjeta | G41: 360 | H41: DOP | I41: =IF(Tx_2026_09[[#This Row],[Monto]]="","",IF(Tx_2026_09[[#This Row],[Moneda]]="USD",Tx_2026_09[[#This Row],[Monto]]*$T$3,Tx_2026_09[[#This Row],[Monto]])) | J41: =IF(Tx_2026_09[[#This Row],[DOP]]="","",Tx_2026_09[[#This Row],[DOP]]/$T$3)
B42: 46273 | C42: Almuerzo | D42: El Conuco | E42: Comida | F42: Tarjeta | G42: 1420 | H42: DOP | I42: =IF(Tx_2026_09[[#This Row],[Monto]]="","",IF(Tx_2026_09[[#This Row],[Moneda]]="USD",Tx_2026_09[[#This Row],[Monto]]*$T$3,Tx_2026_09[[#This Row],[Monto]])) | J42: =IF(Tx_2026_09[[#This Row],[DOP]]="","",Tx_2026_09[[#This Row],[DOP]]/$T$3)
B43: 46276 | C43: Gasolina | D43: Texaco | E43: Transporte | F43: Tarjeta | G43: 2100 | H43: DOP | I43: =IF(Tx_2026_09[[#This Row],[Monto]]="","",IF(Tx_2026_09[[#This Row],[Moneda]]="USD",Tx_2026_09[[#This Row],[Monto]]*$T$3,Tx_2026_09[[#This Row],[Monto]])) | J43: =IF(Tx_2026_09[[#This Row],[DOP]]="","",Tx_2026_09[[#This Row],[DOP]]/$T$3)
B44: 46279 | C44: Cine | D44: Caribbean Cinemas | E44: Entretenimiento | F44: App del banco | G44: 850 | H44: DOP | I44: =IF(Tx_2026_09[[#This Row],[Monto]]="","",IF(Tx_2026_09[[#This Row],[Moneda]]="USD",Tx_2026_09[[#This Row],[Monto]]*$T$3,Tx_2026_09[[#This Row],[Monto]])) | J44: =IF(Tx_2026_09[[#This Row],[DOP]]="","",Tx_2026_09[[#This Row],[DOP]]/$T$3)
...

Sheet Octubre 2026
B1: Finanzas personales | D1: Octubre 2026 | M1: Tasa del mes | N1: ="1 USD = "&FIXED($T$3,2)&" DOP"
B2: Mes nuevo: usa "Cerrar mes" en la página y descarga el Excel, o duplica esta hoja (clic derecho en la pestaña → Mover o copiar → Crear una copia). | T2: Cálculos
T3: =IFERROR(SUMPRODUCT(Env_2026_10[USD],Env_2026_10[Tasa])/SUM(Env_2026_10[USD]),Config!$C$4)
B4: DINERO TOTAL | G4: PRESUPUESTO USADO | J4: =UPPER($D$1) | T4: =SUMIFS(Fijos_2026_10[DOP],Fijos_2026_10[Pagado],"Sí")
B5: =C8*$T$3+C9 | J5: =FIXED(100*$T$8/MAX(1,O6),1)&"% del presupuesto usado" | T5: =SUM(Tx_2026_10[DOP])
B6: =C8+C9/$T$3 | G6: ■ Fijos pagados | I6: =$T$4 | J6: Presupuesto planeado | O6: 70000 | T6: =SUMIFS(Fijos_2026_10[DOP],Fijos_2026_10[Pagado],"No")
T7: =MAX(0,O6-T4-T5-T6)
B8: Cuenta USA | C8: 4320 | D8: USD | G8: ■ Transacciones | I8: =$T$5 | J8: Usado hasta hoy | O8: =$T$8 | T8: =T4+T5
B9: Cuenta RD | C9: 86400 | D9: DOP | G9: ■ Fijos pendientes | I9: =$T$6 | J9: Disponible | O9: =O6-O8 | T9: =FIXED(T8,0)
B10: Ingreso del mes | C10: 5800 | D10: USD | G10: ■ Libre | I10: =$T$7 | J10: Disponible tras fijos pendientes | O10: =O9-$T$6 | T10: ="de "&FIXED(O6,0)&" DOP"
B11: Ingreso − usado | C11: =C10*$T$3-$T$8 | J11: Usado en USD | O11: =$T$8/$T$3
B14: Gastos mensuales | H14: =COUNTIFS(Fijos_2026_10[Pagado],"Sí")&" de "&COUNTA(Fijos_2026_10[Concepto])&" pagados · total "&FIXED(SUM(Fijos_2026_10[DOP]),2)&" DOP" | M14: Por categoría | Q14: DOP
B15: Pagado | C15: Concepto | D15: Día de cobro | E15: Monto | F15: Moneda | G15: DOP | H15: USD | M15: Gastos fijos | O15: =Q15 | Q15: =$T$4
B16: Sí | C16: Luz | E16: 1337.15 | F16: DOP | G16: =IF(Fijos_2026_10[[#This Row],[Monto]]="","",IF(Fijos_2026_10[[#This Row],[Moneda]]="USD",Fijos_2026_10[[#This Row],[Monto]]*$T$3,Fijos_2026_10[[#This Row],[Monto]])) | H16: =IF(Fijos_2026_10[[#This Row],[DOP]]="","",Fijos_2026_10[[#This Row],[DOP]]/$T$3) | M16: Comida | O16: =Q16 | Q16: =SUMIFS(Tx_2026_10[DOP],Tx_2026_10[Categoría],M16)
B17: Sí | C17: Internet | E17: 2699 | F17: DOP | G17: =IF(Fijos_2026_10[[#This Row],[Monto]]="","",IF(Fijos_2026_10[[#This Row],[Moneda]]="USD",Fijos_2026_10[[#This Row],[Monto]]*$T$3,Fijos_2026_10[[#This Row],[Monto]])) | H17: =IF(Fijos_2026_10[[#This Row],[DOP]]="","",Fijos_2026_10[[#This Row],[DOP]]/$T$3) | M17: Supermercado | O17: =Q17 | Q17: =SUMIFS(Tx_2026_10[DOP],Tx_2026_10[Categoría],M17)
B18: Sí | C18: Seguro médico | E18: 5640 | F18: DOP | G18: =IF(Fijos_2026_10[[#This Row],[Monto]]="","",IF(Fijos_2026_10[[#This Row],[Moneda]]="USD",Fijos_2026_10[[#This Row],[Monto]]*$T$3,Fijos_2026_10[[#This Row],[Monto]])) | H18: =IF(Fijos_2026_10[[#This Row],[DOP]]="","",Fijos_2026_10[[#This Row],[DOP]]/$T$3) | M18: Transporte | O18: =Q18 | Q18: =SUMIFS(Tx_2026_10[DOP],Tx_2026_10[Categoría],M18)
B19: Sí | C19: Pago nevera | E19: 15000 | F19: DOP | G19: =IF(Fijos_2026_10[[#This Row],[Monto]]="","",IF(Fijos_2026_10[[#This Row],[Moneda]]="USD",Fijos_2026_10[[#This Row],[Monto]]*$T$3,Fijos_2026_10[[#This Row],[Monto]])) | H19: =IF(Fijos_2026_10[[#This Row],[DOP]]="","",Fijos_2026_10[[#This Row],[DOP]]/$T$3) | M19: Entretenimiento | O19: =Q19 | Q19: =SUMIFS(Tx_2026_10[DOP],Tx_2026_10[Categoría],M19)
B20: Sí | C20: Claude | D20: 5 | E20: 106 | F20: USD | G20: =IF(Fijos_2026_10[[#This Row],[Monto]]="","",IF(Fijos_2026_10[[#This Row],[Moneda]]="USD",Fijos_2026_10[[#This Row],[Monto]]*$T$3,Fijos_2026_10[[#This Row],[Monto]])) | H20: =IF(Fijos_2026_10[[#This Row],[DOP]]="","",Fijos_2026_10[[#This Row],[DOP]]/$T$3) | M20: Salud | O20: =Q20 | Q20: =SUMIFS(Tx_2026_10[DOP],Tx_2026_10[Categoría],M20)
B21: No | C21: Google One | D21: 16 | E21: 121.56 | F21: DOP | G21: =IF(Fijos_2026_10[[#This Row],[Monto]]="","",IF(Fijos_2026_10[[#This Row],[Moneda]]="USD",Fijos_2026_10[[#This Row],[Monto]]*$T$3,Fijos_2026_10[[#This Row],[Monto]])) | H21: =IF(Fijos_2026_10[[#This Row],[DOP]]="","",Fijos_2026_10[[#This Row],[DOP]]/$T$3) | M21: Ropa | O21: =Q21 | Q21: =SUMIFS(Tx_2026_10[DOP],Tx_2026_10[Categoría],M21)
B22: No | C22: iCloud+ | D22: 17 | E22: 604 | F22: DOP | G22: =IF(Fijos_2026_10[[#This Row],[Monto]]="","",IF(Fijos_2026_10[[#This Row],[Moneda]]="USD",Fijos_2026_10[[#This Row],[Monto]]*$T$3,Fijos_2026_10[[#This Row],[Monto]])) | H22: =IF(Fijos_2026_10[[#This Row],[DOP]]="","",Fijos_2026_10[[#This Row],[DOP]]/$T$3) | M22: Hogar | O22: =Q22 | Q22: =SUMIFS(Tx_2026_10[DOP],Tx_2026_10[Categoría],M22)
B23: No | C23: Cluely | E23: 308 | F23: DOP | G23: =IF(Fijos_2026_10[[#This Row],[Monto]]="","",IF(Fijos_2026_10[[#This Row],[Moneda]]="USD",Fijos_2026_10[[#This Row],[Monto]]*$T$3,Fijos_2026_10[[#This Row],[Monto]])) | H23: =IF(Fijos_2026_10[[#This Row],[DOP]]="","",Fijos_2026_10[[#This Row],[DOP]]/$T$3) | M23: Suscripciones | O23: =Q23 | Q23: =SUMIFS(Tx_2026_10[DOP],Tx_2026_10[Categoría],M23)
B24: No | C24: Smartfit | D24: 17 | E24: 1550 | F24: DOP | G24: =IF(Fijos_2026_10[[#This Row],[Monto]]="","",IF(Fijos_2026_10[[#This Row],[Moneda]]="USD",Fijos_2026_10[[#This Row],[Monto]]*$T$3,Fijos_2026_10[[#This Row],[Monto]])) | H24: =IF(Fijos_2026_10[[#This Row],[DOP]]="","",Fijos_2026_10[[#This Row],[DOP]]/$T$3) | M24: Educación | O24: =Q24 | Q24: =SUMIFS(Tx_2026_10[DOP],Tx_2026_10[Categoría],M24)
B25: No | C25: Netflix | E25: 1137.3 | F25: DOP | G25: =IF(Fijos_2026_10[[#This Row],[Monto]]="","",IF(Fijos_2026_10[[#This Row],[Moneda]]="USD",Fijos_2026_10[[#This Row],[Monto]]*$T$3,Fijos_2026_10[[#This Row],[Monto]])) | H25: =IF(Fijos_2026_10[[#This Row],[DOP]]="","",Fijos_2026_10[[#This Row],[DOP]]/$T$3) | M25: Viajes | O25: =Q25 | Q25: =SUMIFS(Tx_2026_10[DOP],Tx_2026_10[Categoría],M25)
B26: Sí | C26: Unicaribe | E26: 7400 | F26: DOP | G26: =IF(Fijos_2026_10[[#This Row],[Monto]]="","",IF(Fijos_2026_10[[#This Row],[Moneda]]="USD",Fijos_2026_10[[#This Row],[Monto]]*$T$3,Fijos_2026_10[[#This Row],[Monto]])) | H26: =IF(Fijos_2026_10[[#This Row],[DOP]]="","",Fijos_2026_10[[#This Row],[DOP]]/$T$3)
G27: =IF(Fijos_2026_10[[#This Row],[Monto]]="","",IF(Fijos_2026_10[[#This Row],[Moneda]]="USD",Fijos_2026_10[[#This Row],[Monto]]*$T$3,Fijos_2026_10[[#This Row],[Monto]])) | H27: =IF(Fijos_2026_10[[#This Row],[DOP]]="","",Fijos_2026_10[[#This Row],[DOP]]/$T$3)
G28: =IF(Fijos_2026_10[[#This Row],[Monto]]="","",IF(Fijos_2026_10[[#This Row],[Moneda]]="USD",Fijos_2026_10[[#This Row],[Monto]]*$T$3,Fijos_2026_10[[#This Row],[Monto]])) | H28: =IF(Fijos_2026_10[[#This Row],[DOP]]="","",Fijos_2026_10[[#This Row],[DOP]]/$T$3) | M28: Envíos USD → DOP | O28: ="Promedio "&FIXED($T$3,2)
G29: =IF(Fijos_2026_10[[#This Row],[Monto]]="","",IF(Fijos_2026_10[[#This Row],[Moneda]]="USD",Fijos_2026_10[[#This Row],[Monto]]*$T$3,Fijos_2026_10[[#This Row],[Monto]])) | H29: =IF(Fijos_2026_10[[#This Row],[DOP]]="","",Fijos_2026_10[[#This Row],[DOP]]/$T$3) | M29: Fecha | N29: Vía | O29: USD | P29: Tasa | Q29: DOP
G30: =IF(Fijos_2026_10[[#This Row],[Monto]]="","",IF(Fijos_2026_10[[#This Row],[Moneda]]="USD",Fijos_2026_10[[#This Row],[Monto]]*$T$3,Fijos_2026_10[[#This Row],[Monto]])) | H30: =IF(Fijos_2026_10[[#This Row],[DOP]]="","",Fijos_2026_10[[#This Row],[DOP]]/$T$3) | M30: 46297 | N30: Remitly | O30: 1500 | P30: 58.76 | Q30: =IF(Env_2026_10[[#This Row],[USD]]="","",Env_2026_10[[#This Row],[USD]]*Env_2026_10[[#This Row],[Tasa]])
Q31: =IF(Env_2026_10[[#This Row],[USD]]="","",Env_2026_10[[#This Row],[USD]]*Env_2026_10[[#This Row],[Tasa]])
Q32: =IF(Env_2026_10[[#This Row],[USD]]="","",Env_2026_10[[#This Row],[USD]]*Env_2026_10[[#This Row],[Tasa]])
Q33: =IF(Env_2026_10[[#This Row],[USD]]="","",Env_2026_10[[#This Row],[USD]]*Env_2026_10[[#This Row],[Tasa]])
Q34: =IF(Env_2026_10[[#This Row],[USD]]="","",Env_2026_10[[#This Row],[USD]]*Env_2026_10[[#This Row],[Tasa]])
B37: Historial de transacciones | H37: =COUNT(Tx_2026_10[Monto])&" transacciones · total "&FIXED($T$5,2)&" DOP"
B38: Fecha | C38: Descripción | D38: Lugar | E38: Categoría | F38: Método | G38: Monto | H38: Moneda | I38: DOP | J38: USD | K38: Notas
B39: 46296 | C39: Compra semanal | D39: Supermercado Nacional | E39: Supermercado | F39: Tarjeta | G39: 4850 | H39: DOP | I39: =IF(Tx_2026_10[[#This Row],[Monto]]="","",IF(Tx_2026_10[[#This Row],[Moneda]]="USD",Tx_2026_10[[#This Row],[Monto]]*$T$3,Tx_2026_10[[#This Row],[Monto]])) | J39: =IF(Tx_2026_10[[#This Row],[DOP]]="","",Tx_2026_10[[#This Row],[DOP]]/$T$3)
B40: 46297 | C40: Uber al trabajo | D40: Uber | E40: Transporte | F40: Tarjeta | G40: 320 | H40: DOP | I40: =IF(Tx_2026_10[[#This Row],[Monto]]="","",IF(Tx_2026_10[[#This Row],[Moneda]]="USD",Tx_2026_10[[#This Row],[Monto]]*$T$3,Tx_2026_10[[#This Row],[Monto]])) | J40: =IF(Tx_2026_10[[#This Row],[DOP]]="","",Tx_2026_10[[#This Row],[DOP]]/$T$3)
B41: 46298 | C41: Almuerzo | D41: Adrian Tropical | E41: Comida | F41: Tarjeta | G41: 1150 | H41: DOP | I41: =IF(Tx_2026_10[[#This Row],[Monto]]="","",IF(Tx_2026_10[[#This Row],[Moneda]]="USD",Tx_2026_10[[#This Row],[Monto]]*$T$3,Tx_2026_10[[#This Row],[Monto]])) | J41: =IF(Tx_2026_10[[#This Row],[DOP]]="","",Tx_2026_10[[#This Row],[DOP]]/$T$3)
B42: 46299 | C42: Cine | D42: Caribbean Cinemas | E42: Entretenimiento | F42: App del banco | G42: 900 | H42: DOP | I42: =IF(Tx_2026_10[[#This Row],[Monto]]="","",IF(Tx_2026_10[[#This Row],[Moneda]]="USD",Tx_2026_10[[#This Row],[Monto]]*$T$3,Tx_2026_10[[#This Row],[Monto]])) | J42: =IF(Tx_2026_10[[#This Row],[DOP]]="","",Tx_2026_10[[#This Row],[DOP]]/$T$3)
B43: 46300 | C43: Farmacia | D43: Farmacia Carol | E43: Salud | F43: Tarjeta | G43: 1240 | H43: DOP | I43: =IF(Tx_2026_10[[#This Row],[Monto]]="","",IF(Tx_2026_10[[#This Row],[Moneda]]="USD",Tx_2026_10[[#This Row],[Monto]]*$T$3,Tx_2026_10[[#This Row],[Monto]])) | J43: =IF(Tx_2026_10[[#This Row],[DOP]]="","",Tx_2026_10[[#This Row],[DOP]]/$T$3)
B44: 46301 | C44: Gasolina | D44: Texaco | E44: Transporte | F44: Tarjeta | G44: 2000 | H44: DOP | I44: =IF(Tx_2026_10[[#This Row],[Monto]]="","",IF(Tx_2026_10[[#This Row],[Moneda]]="USD",Tx_2026_10[[#This Row],[Monto]]*$T$3,Tx_2026_10[[#This Row],[Monto]])) | J44: =IF(Tx_2026_10[[#This Row],[DOP]]="","",Tx_2026_10[[#This Row],[DOP]]/$T$3)
...

Sheet Ahorros
B1: Finanzas personales | D1: Ahorros
R2: Cálculos
B3: MES ACTUAL | C3: DINERO TOTAL (DOP) | F3: PRESUPUESTO | I3: USADO | K3: DISPONIBLE | N3: TASA | R3: =IFERROR(INDIRECT("'"&Config!$C$5&"'!T3"),Config!$C$4)
B4: =Config!$C$5 | C4: =IFERROR(INDIRECT("'"&Config!$C$5&"'!B5"),"") | F4: =IFERROR(INDIRECT("'"&Config!$C$5&"'!O6"),"") | I4: =IFERROR(INDIRECT("'"&Config!$C$5&"'!T8"),"") | K4: =IFERROR(INDIRECT("'"&Config!$C$5&"'!O9"),"") | N4: =IFERROR(INDIRECT("'"&Config!$C$5&"'!T3"),Config!$C$4) | R4: =J12*((YEAR(N12)-YEAR(L12))*12+MONTH(N12)-MONTH(L12)+1)
R5: =SUMIFS(Aportes[USD],Aportes[Meta],"Viaje a Turquía")
B6: Fondo de emergencia | E6: Ahorro personal | I6: Viaje a Turquía | L6: =FIXED(J12,0)&" USD / mes" | R6: =MAX(1,(YEAR(N12)-YEAR(TODAY()))*12+MONTH(N12)-MONTH(TODAY())+1-IF(COUNTIFS(Aportes[Meta],"Viaje a Turquía",Aportes[Mes],Config!$C$5)>0,1,0))
B7: Aportes variables | E7: Aportes variables | I7: ="Faltan "&$R$6&" aportes · "&FIXED($R$7,0)&" USD por mes para llegar" | R7: =MAX(0,R4-R5)/R6
B8: =SUMIFS(Aportes[USD],Aportes[Meta],"Fondo de emergencia") | E8: =SUMIFS(Aportes[USD],Aportes[Meta],"Ahorro personal") | I8: =$R$5 | L8: =$R$5*$R$3 | R8: =IF(R4=0,0,R5/R4)
B9: =B8*$R$3 | E9: =E8*$R$3
I10: =$R$8
B11: =COUNTIFS(Aportes[Meta],"Fondo de emergencia")&" aportes registrados" | E11: =COUNTIFS(Aportes[Meta],"Ahorro personal")&" aportes registrados" | I11: =FIXED(100*$R$8,0)&"% de "&FIXED($R$4,0)&" USD" | L11: ="Meta: "&LOWER(CHOOSE(MONTH(N12),"Enero","Febrero","Marzo","Abril","Mayo","Junio","Julio","Agosto","Septiembre","Octubre","Noviembre","Diciembre"))&" "&YEAR(N12)
I12: Aporte | J12: 3000 | K12: Inicio | L12: 46235 | M12: Fin | N12: 46661
B14: Ingresos por mes | I14: Aportes | L14: ="Total "&FIXED(SUM(Aportes[USD]),2)&" USD"
B15: Mes | C15: Ingreso USD | D15: Tasa | E15: Ingreso DOP | F15: Ahorrado USD | G15: % ahorro | I15: Fecha | J15: Mes | K15: Meta | L15: Monto | M15: Moneda | N15: USD | O15: DOP
B16: Agosto 2026 | C16: =IFERROR(INDIRECT("'"&B16&"'!C10"),"") | D16: =IFERROR(INDIRECT("'"&B16&"'!T3"),"") | E16: =IF(C16="","",C16*D16) | F16: =IF(C16="","",SUMIFS(Aportes[USD],Aportes[Mes],B16)) | G16: =IF(OR(C16="",C16=0),"",F16/C16) | I16: 46237 | J16: =IF(Aportes[[#This Row],[Fecha]]="","",CHOOSE(MONTH(Aportes[[#This Row],[Fecha]]),"Enero","Febrero","Marzo","Abril","Mayo","Junio","Julio","Agosto","Septiembre","Octubre","Noviembre","Diciembre")&" "&YEAR(Aportes[[#This Row],[Fecha]])) | K16: Viaje a Turquía | L16: 3000 | M16: USD | N16: =IF(Aportes[[#This Row],[Monto]]="","",IF(Aportes[[#This Row],[Moneda]]="USD",Aportes[[#This Row],[Monto]],Aportes[[#This Row],[Monto]]/IFERROR(INDIRECT("'"&Aportes[[#This Row],[Mes]]&"'!T3"),Config!$C$4))) | O16: =IF(Aportes[[#This Row],[USD]]="","",Aportes[[#This Row],[USD]]*IFERROR(INDIRECT("'"&Aportes[[#This Row],[Mes]]&"'!T3"),Config!$C$4))
B17: Septiembre 2026 | C17: =IFERROR(INDIRECT("'"&B17&"'!C10"),"") | D17: =IFERROR(INDIRECT("'"&B17&"'!T3"),"") | E17: =IF(C17="","",C17*D17) | F17: =IF(C17="","",SUMIFS(Aportes[USD],Aportes[Mes],B17)) | G17: =IF(OR(C17="",C17=0),"",F17/C17) | I17: 46237 | J17: =IF(Aportes[[#This Row],[Fecha]]="","",CHOOSE(MONTH(Aportes[[#This Row],[Fecha]]),"Enero","Febrero","Marzo","Abril","Mayo","Junio","Julio","Agosto","Septiembre","Octubre","Noviembre","Diciembre")&" "&YEAR(Aportes[[#This Row],[Fecha]])) | K17: Fondo de emergencia | L17: 400 | M17: USD | N17: =IF(Aportes[[#This Row],[Monto]]="","",IF(Aportes[[#This Row],[Moneda]]="USD",Aportes[[#This Row],[Monto]],Aportes[[#This Row],[Monto]]/IFERROR(INDIRECT("'"&Aportes[[#This Row],[Mes]]&"'!T3"),Config!$C$4))) | O17: =IF(Aportes[[#This Row],[USD]]="","",Aportes[[#This Row],[USD]]*IFERROR(INDIRECT("'"&Aportes[[#This Row],[Mes]]&"'!T3"),Config!$C$4))
B18: Octubre 2026 | C18: =IFERROR(INDIRECT("'"&B18&"'!C10"),"") | D18: =IFERROR(INDIRECT("'"&B18&"'!T3"),"") | E18: =IF(C18="","",C18*D18) | F18: =IF(C18="","",SUMIFS(Aportes[USD],Aportes[Mes],B18)) | G18: =IF(OR(C18="",C18=0),"",F18/C18) | I18: 46254 | J18: =IF(Aportes[[#This Row],[Fecha]]="","",CHOOSE(MONTH(Aportes[[#This Row],[Fecha]]),"Enero","Febrero","Marzo","Abril","Mayo","Junio","Julio","Agosto","Septiembre","Octubre","Noviembre","Diciembre")&" "&YEAR(Aportes[[#This Row],[Fecha]])) | K18: Ahorro personal | L18: 250 | M18: USD | N18: =IF(Aportes[[#This Row],[Monto]]="","",IF(Aportes[[#This Row],[Moneda]]="USD",Aportes[[#This Row],[Monto]],Aportes[[#This Row],[Monto]]/IFERROR(INDIRECT("'"&Aportes[[#This Row],[Mes]]&"'!T3"),Config!$C$4))) | O18: =IF(Aportes[[#This Row],[USD]]="","",Aportes[[#This Row],[USD]]*IFERROR(INDIRECT("'"&Aportes[[#This Row],[Mes]]&"'!T3"),Config!$C$4))
B19: Noviembre 2026 | C19: =IFERROR(INDIRECT("'"&B19&"'!C10"),"") | D19: =IFERROR(INDIRECT("'"&B19&"'!T3"),"") | E19: =IF(C19="","",C19*D19) | F19: =IF(C19="","",SUMIFS(Aportes[USD],Aportes[Mes],B19)) | G19: =IF(OR(C19="",C19=0),"",F19/C19) | I19: 46267 | J19: =IF(Aportes[[#This Row],[Fecha]]="","",CHOOSE(MONTH(Aportes[[#This Row],[Fecha]]),"Enero","Febrero","Marzo","Abril","Mayo","Junio","Julio","Agosto","Septiembre","Octubre","Noviembre","Diciembre")&" "&YEAR(Aportes[[#This Row],[Fecha]])) | K19: Viaje a Turquía | L19: 3000 | M19: USD | N19: =IF(Aportes[[#This Row],[Monto]]="","",IF(Aportes[[#This Row],[Moneda]]="USD",Aportes[[#This Row],[Monto]],Aportes[[#This Row],[Monto]]/IFERROR(INDIRECT("'"&Aportes[[#This Row],[Mes]]&"'!T3"),Config!$C$4))) | O19: =IF(Aportes[[#This Row],[USD]]="","",Aportes[[#This Row],[USD]]*IFERROR(INDIRECT("'"&Aportes[[#This Row],[Mes]]&"'!T3"),Config!$C$4))
B20: Diciembre 2026 | C20: =IFERROR(INDIRECT("'"&B20&"'!C10"),"") | D20: =IFERROR(INDIRECT("'"&B20&"'!T3"),"") | E20: =IF(C20="","",C20*D20) | F20: =IF(C20="","",SUMIFS(Aportes[USD],Aportes[Mes],B20)) | G20: =IF(OR(C20="",C20=0),"",F20/C20) | I20: 46267 | J20: =IF(Aportes[[#This Row],[Fecha]]="","",CHOOSE(MONTH(Aportes[[#This Row],[Fecha]]),"Enero","Febrero","Marzo","Abril","Mayo","Junio","Julio","Agosto","Septiembre","Octubre","Noviembre","Diciembre")&" "&YEAR(Aportes[[#This Row],[Fecha]])) | K20: Fondo de emergencia | L20: 300 | M20: USD | N20: =IF(Aportes[[#This Row],[Monto]]="","",IF(Aportes[[#This Row],[Moneda]]="USD",Aportes[[#This Row],[Monto]],Aportes[[#This Row],[Monto]]/IFERROR(INDIRECT("'"&Aportes[[#This Row],[Mes]]&"'!T3"),Config!$C$4))) | O20: =IF(Aportes[[#This Row],[USD]]="","",Aportes[[#This Row],[USD]]*IFERROR(INDIRECT("'"&Aportes[[#This Row],[Mes]]&"'!T3"),Config!$C$4))
B21: Enero 2027 | C21: =IFERROR(INDIRECT("'"&B21&"'!C10"),"") | D21: =IFERROR(INDIRECT("'"&B21&"'!T3"),"") | E21: =IF(C21="","",C21*D21) | F21: =IF(C21="","",SUMIFS(Aportes[USD],Aportes[Mes],B21)) | G21: =IF(OR(C21="",C21=0),"",F21/C21) | I21: 46283 | J21: =IF(Aportes[[#This Row],[Fecha]]="","",CHOOSE(MONTH(Aportes[[#This Row],[Fecha]]),"Enero","Febrero","Marzo","Abril","Mayo","Junio","Julio","Agosto","Septiembre","Octubre","Noviembre","Diciembre")&" "&YEAR(Aportes[[#This Row],[Fecha]])) | K21: Ahorro personal | L21: 200 | M21: USD | N21: =IF(Aportes[[#This Row],[Monto]]="","",IF(Aportes[[#This Row],[Moneda]]="USD",Aportes[[#This Row],[Monto]],Aportes[[#This Row],[Monto]]/IFERROR(INDIRECT("'"&Aportes[[#This Row],[Mes]]&"'!T3"),Config!$C$4))) | O21: =IF(Aportes[[#This Row],[USD]]="","",Aportes[[#This Row],[USD]]*IFERROR(INDIRECT("'"&Aportes[[#This Row],[Mes]]&"'!T3"),Config!$C$4))
B22: Febrero 2027 | C22: =IFERROR(INDIRECT("'"&B22&"'!C10"),"") | D22: =IFERROR(INDIRECT("'"&B22&"'!T3"),"") | E22: =IF(C22="","",C22*D22) | F22: =IF(C22="","",SUMIFS(Aportes[USD],Aportes[Mes],B22)) | G22: =IF(OR(C22="",C22=0),"",F22/C22) | I22: 46298 | J22: =IF(Aportes[[#This Row],[Fecha]]="","",CHOOSE(MONTH(Aportes[[#This Row],[Fecha]]),"Enero","Febrero","Marzo","Abril","Mayo","Junio","Julio","Agosto","Septiembre","Octubre","Noviembre","Diciembre")&" "&YEAR(Aportes[[#This Row],[Fecha]])) | K22: Viaje a Turquía | L22: 3000 | M22: USD | N22: =IF(Aportes[[#This Row],[Monto]]="","",IF(Aportes[[#This Row],[Moneda]]="USD",Aportes[[#This Row],[Monto]],Aportes[[#This Row],[Monto]]/IFERROR(INDIRECT("'"&Aportes[[#This Row],[Mes]]&"'!T3"),Config!$C$4))) | O22: =IF(Aportes[[#This Row],[USD]]="","",Aportes[[#This Row],[USD]]*IFERROR(INDIRECT("'"&Aportes[[#This Row],[Mes]]&"'!T3"),Config!$C$4))
B23: Marzo 2027 | C23: =IFERROR(INDIRECT("'"&B23&"'!C10"),"") | D23: =IFERROR(INDIRECT("'"&B23&"'!T3"),"") | E23: =IF(C23="","",C23*D23) | F23: =IF(C23="","",SUMIFS(Aportes[USD],Aportes[Mes],B23)) | G23: =IF(OR(C23="",C23=0),"",F23/C23) | I23: 46298 | J23: =IF(Aportes[[#This Row],[Fecha]]="","",CHOOSE(MONTH(Aportes[[#This Row],[Fecha]]),"Enero","Febrero","Marzo","Abril","Mayo","Junio","Julio","Agosto","Septiembre","Octubre","Noviembre","Diciembre")&" "&YEAR(Aportes[[#This Row],[Fecha]])) | K23: Fondo de emergencia | L23: 500 | M23: USD | N23: =IF(Aportes[[#This Row],[Monto]]="","",IF(Aportes[[#This Row],[Moneda]]="USD",Aportes[[#This Row],[Monto]],Aportes[[#This Row],[Monto]]/IFERROR(INDIRECT("'"&Aportes[[#This Row],[Mes]]&"'!T3"),Config!$C$4))) | O23: =IF(Aportes[[#This Row],[USD]]="","",Aportes[[#This Row],[USD]]*IFERROR(INDIRECT("'"&Aportes[[#This Row],[Mes]]&"'!T3"),Config!$C$4))
B24: Abril 2027 | C24: =IFERROR(INDIRECT("'"&B24&"'!C10"),"") | D24: =IFERROR(INDIRECT("'"&B24&"'!T3"),"") | E24: =IF(C24="","",C24*D24) | F24: =IF(C24="","",SUMIFS(Aportes[USD],Aportes[Mes],B24)) | G24: =IF(OR(C24="",C24=0),"",F24/C24) | J24: =IF(Aportes[[#This Row],[Fecha]]="","",CHOOSE(MONTH(Aportes[[#This Row],[Fecha]]),"Enero","Febrero","Marzo","Abril","Mayo","Junio","Julio","Agosto","Septiembre","Octubre","Noviembre","Diciembre")&" "&YEAR(Aportes[[#This Row],[Fecha]])) | N24: =IF(Aportes[[#This Row],[Monto]]="","",IF(Aportes[[#This Row],[Moneda]]="USD",Aportes[[#This Row],[Monto]],Aportes[[#This Row],[Monto]]/IFERROR(INDIRECT("'"&Aportes[[#This Row],[Mes]]&"'!T3"),Config!$C$4))) | O24: =IF(Aportes[[#This Row],[USD]]="","",Aportes[[#This Row],[USD]]*IFERROR(INDIRECT("'"&Aportes[[#This Row],[Mes]]&"'!T3"),Config!$C$4))
B25: Mayo 2027 | C25: =IFERROR(INDIRECT("'"&B25&"'!C10"),"") | D25: =IFERROR(INDIRECT("'"&B25&"'!T3"),"") | E25: =IF(C25="","",C25*D25) | F25: =IF(C25="","",SUMIFS(Aportes[USD],Aportes[Mes],B25)) | G25: =IF(OR(C25="",C25=0),"",F25/C25) | J25: =IF(Aportes[[#This Row],[Fecha]]="","",CHOOSE(MONTH(Aportes[[#This Row],[Fecha]]),"Enero","Febrero","Marzo","Abril","Mayo","Junio","Julio","Agosto","Septiembre","Octubre","Noviembre","Diciembre")&" "&YEAR(Aportes[[#This Row],[Fecha]])) | N25: =IF(Aportes[[#This Row],[Monto]]="","",IF(Aportes[[#This Row],[Moneda]]="USD",Aportes[[#This Row],[Monto]],Aportes[[#This Row],[Monto]]/IFERROR(INDIRECT("'"&Aportes[[#This Row],[Mes]]&"'!T3"),Config!$C$4))) | O25: =IF(Aportes[[#This Row],[USD]]="","",Aportes[[#This Row],[USD]]*IFERROR(INDIRECT("'"&Aportes[[#This Row],[Mes]]&"'!T3"),Config!$C$4))
B26: Junio 2027 | C26: =IFERROR(INDIRECT("'"&B26&"'!C10"),"") | D26: =IFERROR(INDIRECT("'"&B26&"'!T3"),"") | E26: =IF(C26="","",C26*D26) | F26: =IF(C26="","",SUMIFS(Aportes[USD],Aportes[Mes],B26)) | G26: =IF(OR(C26="",C26=0),"",F26/C26) | J26: =IF(Aportes[[#This Row],[Fecha]]="","",CHOOSE(MONTH(Aportes[[#This Row],[Fecha]]),"Enero","Febrero","Marzo","Abril","Mayo","Junio","Julio","Agosto","Septiembre","Octubre","Noviembre","Diciembre")&" "&YEAR(Aportes[[#This Row],[Fecha]])) | N26: =IF(Aportes[[#This Row],[Monto]]="","",IF(Aportes[[#This Row],[Moneda]]="USD",Aportes[[#This Row],[Monto]],Aportes[[#This Row],[Monto]]/IFERROR(INDIRECT("'"&Aportes[[#This Row],[Mes]]&"'!T3"),Config!$C$4))) | O26: =IF(Aportes[[#This Row],[USD]]="","",Aportes[[#This Row],[USD]]*IFERROR(INDIRECT("'"&Aportes[[#This Row],[Mes]]&"'!T3"),Config!$C$4))
B27: Julio 2027 | C27: =IFERROR(INDIRECT("'"&B27&"'!C10"),"") | D27: =IFERROR(INDIRECT("'"&B27&"'!T3"),"") | E27: =IF(C27="","",C27*D27) | F27: =IF(C27="","",SUMIFS(Aportes[USD],Aportes[Mes],B27)) | G27: =IF(OR(C27="",C27=0),"",F27/C27) | J27: =IF(Aportes[[#This Row],[Fecha]]="","",CHOOSE(MONTH(Aportes[[#This Row],[Fecha]]),"Enero","Febrero","Marzo","Abril","Mayo","Junio","Julio","Agosto","Septiembre","Octubre","Noviembre","Diciembre")&" "&YEAR(Aportes[[#This Row],[Fecha]])) | N27: =IF(Aportes[[#This Row],[Monto]]="","",IF(Aportes[[#This Row],[Moneda]]="USD",Aportes[[#This Row],[Monto]],Aportes[[#This Row],[Monto]]/IFERROR(INDIRECT("'"&Aportes[[#This Row],[Mes]]&"'!T3"),Config!$C$4))) | O27: =IF(Aportes[[#This Row],[USD]]="","",Aportes[[#This Row],[USD]]*IFERROR(INDIRECT("'"&Aportes[[#This Row],[Mes]]&"'!T3"),Config!$C$4))
B28: Agosto 2027 | C28: =IFERROR(INDIRECT("'"&B28&"'!C10"),"") | D28: =IFERROR(INDIRECT("'"&B28&"'!T3"),"") | E28: =IF(C28="","",C28*D28) | F28: =IF(C28="","",SUMIFS(Aportes[USD],Aportes[Mes],B28)) | G28: =IF(OR(C28="",C28=0),"",F28/C28) | J28: =IF(Aportes[[#This Row],[Fecha]]="","",CHOOSE(MONTH(Aportes[[#This Row],[Fecha]]),"Enero","Febrero","Marzo","Abril","Mayo","Junio","Julio","Agosto","Septiembre","Octubre","Noviembre","Diciembre")&" "&YEAR(Aportes[[#This Row],[Fecha]])) | N28: =IF(Aportes[[#This Row],[Monto]]="","",IF(Aportes[[#This Row],[Moneda]]="USD",Aportes[[#This Row],[Monto]],Aportes[[#This Row],[Monto]]/IFERROR(INDIRECT("'"&Aportes[[#This Row],[Mes]]&"'!T3"),Config!$C$4))) | O28: =IF(Aportes[[#This Row],[USD]]="","",Aportes[[#This Row],[USD]]*IFERROR(INDIRECT("'"&Aportes[[#This Row],[Mes]]&"'!T3"),Config!$C$4))
B29: Septiembre 2027 | C29: =IFERROR(INDIRECT("'"&B29&"'!C10"),"") | D29: =IFERROR(INDIRECT("'"&B29&"'!T3"),"") | E29: =IF(C29="","",C29*D29) | F29: =IF(C29="","",SUMIFS(Aportes[USD],Aportes[Mes],B29)) | G29: =IF(OR(C29="",C29=0),"",F29/C29) | J29: =IF(Aportes[[#This Row],[Fecha]]="","",CHOOSE(MONTH(Aportes[[#This Row],[Fecha]]),"Enero","Febrero","Marzo","Abril","Mayo","Junio","Julio","Agosto","Septiembre","Octubre","Noviembre","Diciembre")&" "&YEAR(Aportes[[#This Row],[Fecha]])) | N29: =IF(Aportes[[#This Row],[Monto]]="","",IF(Aportes[[#This Row],[Moneda]]="USD",Aportes[[#This Row],[Monto]],Aportes[[#This Row],[Monto]]/IFERROR(INDIRECT("'"&Aportes[[#This Row],[Mes]]&"'!T3"),Config!$C$4))) | O29: =IF(Aportes[[#This Row],[USD]]="","",Aportes[[#This Row],[USD]]*IFERROR(INDIRECT("'"&Aportes[[#This Row],[Mes]]&"'!T3"),Config!$C$4))
B30: Octubre 2027 | C30: =IFERROR(INDIRECT("'"&B30&"'!C10"),"") | D30: =IFERROR(INDIRECT("'"&B30&"'!T3"),"") | E30: =IF(C30="","",C30*D30) | F30: =IF(C30="","",SUMIFS(Aportes[USD],Aportes[Mes],B30)) | G30: =IF(OR(C30="",C30=0),"",F30/C30) | J30: =IF(Aportes[[#This Row],[Fecha]]="","",CHOOSE(MONTH(Aportes[[#This Row],[Fecha]]),"Enero","Febrero","Marzo","Abril","Mayo","Junio","Julio","Agosto","Septiembre","Octubre","Noviembre","Diciembre")&" "&YEAR(Aportes[[#This Row],[Fecha]])) | N30: =IF(Aportes[[#This Row],[Monto]]="","",IF(Aportes[[#This Row],[Moneda]]="USD",Aportes[[#This Row],[Monto]],Aportes[[#This Row],[Monto]]/IFERROR(INDIRECT("'"&Aportes[[#This Row],[Mes]]&"'!T3"),Config!$C$4))) | O30: =IF(Aportes[[#This Row],[USD]]="","",Aportes[[#This Row],[USD]]*IFERROR(INDIRECT("'"&Aportes[[#This Row],[Mes]]&"'!T3"),Config!$C$4))
J31: =IF(Aportes[[#This Row],[Fecha]]="","",CHOOSE(MONTH(Aportes[[#This Row],[Fecha]]),"Enero","Febrero","Marzo","Abril","Mayo","Junio","Julio","Agosto","Septiembre","Octubre","Noviembre","Diciembre")&" "&YEAR(Aportes[[#This Row],[Fecha]])) | N31: =IF(Aportes[[#This Row],[Monto]]="","",IF(Aportes[[#This Row],[Moneda]]="USD",Aportes[[#This Row],[Monto]],Aportes[[#This Row],[Monto]]/IFERROR(INDIRECT("'"&Aportes[[#This Row],[Mes]]&"'!T3"),Config!$C$4))) | O31: =IF(Aportes[[#This Row],[USD]]="","",Aportes[[#This Row],[USD]]*IFERROR(INDIRECT("'"&Aportes[[#This Row],[Mes]]&"'!T3"),Config!$C$4))
J32: =IF(Aportes[[#This Row],[Fecha]]="","",CHOOSE(MONTH(Aportes[[#This Row],[Fecha]]),"Enero","Febrero","Marzo","Abril","Mayo","Junio","Julio","Agosto","Septiembre","Octubre","Noviembre","Diciembre")&" "&YEAR(Aportes[[#This Row],[Fecha]])) | N32: =IF(Aportes[[#This Row],[Monto]]="","",IF(Aportes[[#This Row],[Moneda]]="USD",Aportes[[#This Row],[Monto]],Aportes[[#This Row],[Monto]]/IFERROR(INDIRECT("'"&Aportes[[#This Row],[Mes]]&"'!T3"),Config!$C$4))) | O32: =IF(Aportes[[#This Row],[USD]]="","",Aportes[[#This Row],[USD]]*IFERROR(INDIRECT("'"&Aportes[[#This Row],[Mes]]&"'!T3"),Config!$C$4))
J33: =IF(Aportes[[#This Row],[Fecha]]="","",CHOOSE(MONTH(Aportes[[#This Row],[Fecha]]),"Enero","Febrero","Marzo","Abril","Mayo","Junio","Julio","Agosto","Septiembre","Octubre","Noviembre","Diciembre")&" "&YEAR(Aportes[[#This Row],[Fecha]])) | N33: =IF(Aportes[[#This Row],[Monto]]="","",IF(Aportes[[#This Row],[Moneda]]="USD",Aportes[[#This Row],[Monto]],Aportes[[#This Row],[Monto]]/IFERROR(INDIRECT("'"&Aportes[[#This Row],[Mes]]&"'!T3"),Config!$C$4))) | O33: =IF(Aportes[[#This Row],[USD]]="","",Aportes[[#This Row],[USD]]*IFERROR(INDIRECT("'"&Aportes[[#This Row],[Mes]]&"'!T3"),Config!$C$4))

Sheet Config
B1: Configuración
B3: AJUSTES | E3: CATEGORÍAS | F3: MÉTODOS DE PAGO | G3: METAS DE AHORRO
B4: Tasa por defecto (mes sin envíos) | C4: 58.76 | E4: Comida | F4: Tarjeta | G4: Fondo de emergencia
B5: Mes actual (se muestra en Ahorros) | C5: Octubre 2026 | E5: Supermercado | F5: Transferencia | G5: Ahorro personal
E6: Transporte | F6: App del banco | G6: Viaje a Turquía
E7: Entretenimiento
E8: Salud
E9: Ropa
E10: Hogar
E11: Suscripciones
E12: Educación
E13: Viajes
