Workbook

Sheet Ağustos 2026
B1: FE Finance | D1: Ağustos 2026 | M1: Ay kuru | N1: ="1 USD = "&FIXED($T$3,2)&" DOP" -> 1 USD = 58.18 DOP
B2: Yeni ay: sayfada ayı kapatıp Excel'i indirin veya bu sayfayı çoğaltın (sekmeye sağ tıklayın → Taşı veya Kopyala → Kopya oluştur). | T2: Hesaplamalar
T3: =IFERROR(SUMPRODUCT(Transfer_2026_08[USD],Transfer_2026_08[Kur])/SUM(Transfer_2026_08[USD]),Config!$C$4) -> 58.183333
B4: TOPLAM PARA | G4: KULLANILAN BÜTÇE | J4: =UPPER($D$1) -> AĞUSTOS 2026 | T4: =SUMIFS(Sabit_2026_08[DOP],Sabit_2026_08[Ödendi],"Evet") -> 41917.693
B5: =C8*$T$3+C9 -> 305115 | J5: ="Kullanılan bütçe: %"&FIXED(100*$T$8/MAX(1,O6),1) -> Kullanılan bütçe: %99.7 | T5: =SUM(Islem_2026_08[DOP]) -> 27850
B6: =C8+C9/$T$3 -> 5244.0275 | G6: ■ Ödenen sabitler | I6: =$T$4 -> 41917.693 | J6: Planlanan bütçe | O6: 70000 | T6: =SUMIFS(Sabit_2026_08[DOP],Sabit_2026_08[Ödendi],"Hayır") -> 0
T7: =MAX(0,O6-T4-T5-T6) -> 232.30667
B8: ABD hesabı | C8: 3900 | D8: USD | G8: ■ İşlemler | I8: =$T$5 -> 27850 | J8: Bugüne kadar kullanılan | O8: =$T$8 -> 69767.693 | T8: =T4+T5 -> 69767.693
B9: DC hesabı | C9: 78200 | D9: DOP | G9: ■ Bekleyen sabitler | I9: =$T$6 -> 0 | J9: Kalan | O9: =O6-O8 -> 232.30667 | T9: =FIXED(T8,0) -> 69,768
B10: Ayın geliri | C10: 5800 | D10: USD | G10: ■ Serbest | I10: =$T$7 -> 232.30667 | J10: Bekleyen sabitlerden sonra kalan | O10: =O9-$T$6 -> 232.30667 | T10: ="/ "&FIXED(O6,0)&" DOP" -> / 70,000 DOP
B11: Gelir − kullanılan | C11: =C10*$T$3-$T$8 -> 267695.64 | J11: USD olarak kullanılan | O11: =$T$8/$T$3 -> 1199.101
B14: Aylık giderler | H14: =COUNTIFS(Sabit_2026_08[Ödendi],"Evet")&" / "&COUNTA(Sabit_2026_08[Kalem])&" ödendi · toplam "&FIXED(SUM(Sabit_2026_08[DOP]),2)&" DOP" -> 11 / 11 ödendi · toplam 41,917.69 DOP | M14: Kategoriye göre | Q14: DOP
B15: Ödendi | C15: Kalem | D15: Gün | E15: Tutar | F15: Para birimi | G15: DOP | H15: USD | M15: Sabit giderler | O15: =Q15 -> 41917.693 | Q15: =$T$4 -> 41917.693
B16: Evet | C16: Electricity | E16: 1290.4 | F16: DOP | G16: =IF(Sabit_2026_08[[#This Row],[Tutar]]="","",IF(Sabit_2026_08[[#This Row],[Para birimi]]="USD",Sabit_2026_08[[#This Row],[Tutar]]*$T$3,Sabit_2026_08[[#This Row],[Tutar]])) -> 1290.4 | H16: =IF(Sabit_2026_08[[#This Row],[DOP]]="","",Sabit_2026_08[[#This Row],[DOP]]/$T$3) -> 22.178172 | M16: Yemek | O16: =Q16 -> 4430 | Q16: =SUMIFS(Islem_2026_08[DOP],Islem_2026_08[Kategori],M16) -> 4430
B17: Evet | C17: Internet | E17: 2699 | F17: DOP | G17: =IF(Sabit_2026_08[[#This Row],[Tutar]]="","",IF(Sabit_2026_08[[#This Row],[Para birimi]]="USD",Sabit_2026_08[[#This Row],[Tutar]]*$T$3,Sabit_2026_08[[#This Row],[Tutar]])) -> 2699 | H17: =IF(Sabit_2026_08[[#This Row],[DOP]]="","",Sabit_2026_08[[#This Row],[DOP]]/$T$3) -> 46.387854 | M17: Market | O17: =Q17 -> 9910 | Q17: =SUMIFS(Islem_2026_08[DOP],Islem_2026_08[Kategori],M17) -> 9910
B18: Evet | C18: Health insurance | E18: 5640 | F18: DOP | G18: =IF(Sabit_2026_08[[#This Row],[Tutar]]="","",IF(Sabit_2026_08[[#This Row],[Para birimi]]="USD",Sabit_2026_08[[#This Row],[Tutar]]*$T$3,Sabit_2026_08[[#This Row],[Tutar]])) -> 5640 | H18: =IF(Sabit_2026_08[[#This Row],[DOP]]="","",Sabit_2026_08[[#This Row],[DOP]]/$T$3) -> 96.934976 | M18: Ulaşım | O18: =Q18 -> 4610 | Q18: =SUMIFS(Islem_2026_08[DOP],Islem_2026_08[Kategori],M18) -> 4610
B19: Evet | C19: Fridge payment | E19: 15000 | F19: DOP | G19: =IF(Sabit_2026_08[[#This Row],[Tutar]]="","",IF(Sabit_2026_08[[#This Row],[Para birimi]]="USD",Sabit_2026_08[[#This Row],[Tutar]]*$T$3,Sabit_2026_08[[#This Row],[Tutar]])) -> 15000 | H19: =IF(Sabit_2026_08[[#This Row],[DOP]]="","",Sabit_2026_08[[#This Row],[DOP]]/$T$3) -> 257.80579 | M19: Eğlence | O19: =Q19 -> 2500 | Q19: =SUMIFS(Islem_2026_08[DOP],Islem_2026_08[Kategori],M19) -> 2500
B20: Evet | C20: Claude | D20: 5 | E20: 106 | F20: USD | G20: =IF(Sabit_2026_08[[#This Row],[Tutar]]="","",IF(Sabit_2026_08[[#This Row],[Para birimi]]="USD",Sabit_2026_08[[#This Row],[Tutar]]*$T$3,Sabit_2026_08[[#This Row],[Tutar]])) -> 6167.4333 | H20: =IF(Sabit_2026_08[[#This Row],[DOP]]="","",Sabit_2026_08[[#This Row],[DOP]]/$T$3) -> 106 | M20: Sağlık | O20: =Q20 -> 2500 | Q20: =SUMIFS(Islem_2026_08[DOP],Islem_2026_08[Kategori],M20) -> 2500
B21: Evet | C21: Google One | D21: 16 | E21: 121.56 | F21: DOP | G21: =IF(Sabit_2026_08[[#This Row],[Tutar]]="","",IF(Sabit_2026_08[[#This Row],[Para birimi]]="USD",Sabit_2026_08[[#This Row],[Tutar]]*$T$3,Sabit_2026_08[[#This Row],[Tutar]])) -> 121.56 | H21: =IF(Sabit_2026_08[[#This Row],[DOP]]="","",Sabit_2026_08[[#This Row],[DOP]]/$T$3) -> 2.0892581 | M21: Giyim | O21: =Q21 -> 3900 | Q21: =SUMIFS(Islem_2026_08[DOP],Islem_2026_08[Kategori],M21) -> 3900
B22: Evet | C22: iCloud+ | D22: 17 | E22: 604 | F22: DOP | G22: =IF(Sabit_2026_08[[#This Row],[Tutar]]="","",IF(Sabit_2026_08[[#This Row],[Para birimi]]="USD",Sabit_2026_08[[#This Row],[Tutar]]*$T$3,Sabit_2026_08[[#This Row],[Tutar]])) -> 604 | H22: =IF(Sabit_2026_08[[#This Row],[DOP]]="","",Sabit_2026_08[[#This Row],[DOP]]/$T$3) -> 10.38098 | M22: Ev | O22: =Q22 -> 0 | Q22: =SUMIFS(Islem_2026_08[DOP],Islem_2026_08[Kategori],M22) -> 0
B23: Evet | C23: Cluely | E23: 308 | F23: DOP | G23: =IF(Sabit_2026_08[[#This Row],[Tutar]]="","",IF(Sabit_2026_08[[#This Row],[Para birimi]]="USD",Sabit_2026_08[[#This Row],[Tutar]]*$T$3,Sabit_2026_08[[#This Row],[Tutar]])) -> 308 | H23: =IF(Sabit_2026_08[[#This Row],[DOP]]="","",Sabit_2026_08[[#This Row],[DOP]]/$T$3) -> 5.2936121 | M23: Abonelikler | O23: =Q23 -> 0 | Q23: =SUMIFS(Islem_2026_08[DOP],Islem_2026_08[Kategori],M23) -> 0
B24: Evet | C24: Smartfit | D24: 17 | E24: 1550 | F24: DOP | G24: =IF(Sabit_2026_08[[#This Row],[Tutar]]="","",IF(Sabit_2026_08[[#This Row],[Para birimi]]="USD",Sabit_2026_08[[#This Row],[Tutar]]*$T$3,Sabit_2026_08[[#This Row],[Tutar]])) -> 1550 | H24: =IF(Sabit_2026_08[[#This Row],[DOP]]="","",Sabit_2026_08[[#This Row],[DOP]]/$T$3) -> 26.639931 | M24: Eğitim | O24: =Q24 -> 0 | Q24: =SUMIFS(Islem_2026_08[DOP],Islem_2026_08[Kategori],M24) -> 0
B25: Evet | C25: Netflix | E25: 1137.3 | F25: DOP | G25: =IF(Sabit_2026_08[[#This Row],[Tutar]]="","",IF(Sabit_2026_08[[#This Row],[Para birimi]]="USD",Sabit_2026_08[[#This Row],[Tutar]]*$T$3,Sabit_2026_08[[#This Row],[Tutar]])) -> 1137.3 | H25: =IF(Sabit_2026_08[[#This Row],[DOP]]="","",Sabit_2026_08[[#This Row],[DOP]]/$T$3) -> 19.546835 | M25: Seyahat | O25: =Q25 -> 0 | Q25: =SUMIFS(Islem_2026_08[DOP],Islem_2026_08[Kategori],M25) -> 0
B26: Evet | C26: Unicaribe | E26: 7400 | F26: DOP | G26: =IF(Sabit_2026_08[[#This Row],[Tutar]]="","",IF(Sabit_2026_08[[#This Row],[Para birimi]]="USD",Sabit_2026_08[[#This Row],[Tutar]]*$T$3,Sabit_2026_08[[#This Row],[Tutar]])) -> 7400 | H26: =IF(Sabit_2026_08[[#This Row],[DOP]]="","",Sabit_2026_08[[#This Row],[DOP]]/$T$3) -> 127.18419
G27: =IF(Sabit_2026_08[[#This Row],[Tutar]]="","",IF(Sabit_2026_08[[#This Row],[Para birimi]]="USD",Sabit_2026_08[[#This Row],[Tutar]]*$T$3,Sabit_2026_08[[#This Row],[Tutar]])) | H27: =IF(Sabit_2026_08[[#This Row],[DOP]]="","",Sabit_2026_08[[#This Row],[DOP]]/$T$3)
G28: =IF(Sabit_2026_08[[#This Row],[Tutar]]="","",IF(Sabit_2026_08[[#This Row],[Para birimi]]="USD",Sabit_2026_08[[#This Row],[Tutar]]*$T$3,Sabit_2026_08[[#This Row],[Tutar]])) | H28: =IF(Sabit_2026_08[[#This Row],[DOP]]="","",Sabit_2026_08[[#This Row],[DOP]]/$T$3) | M28: Transferler USD → DOP | O28: ="Ortalama "&FIXED($T$3,2) -> Ortalama 58.18
G29: =IF(Sabit_2026_08[[#This Row],[Tutar]]="","",IF(Sabit_2026_08[[#This Row],[Para birimi]]="USD",Sabit_2026_08[[#This Row],[Tutar]]*$T$3,Sabit_2026_08[[#This Row],[Tutar]])) | H29: =IF(Sabit_2026_08[[#This Row],[DOP]]="","",Sabit_2026_08[[#This Row],[DOP]]/$T$3) | M29: Tarih | N29: Kanal | O29: USD | P29: Kur | Q29: DOP
G30: =IF(Sabit_2026_08[[#This Row],[Tutar]]="","",IF(Sabit_2026_08[[#This Row],[Para birimi]]="USD",Sabit_2026_08[[#This Row],[Tutar]]*$T$3,Sabit_2026_08[[#This Row],[Tutar]])) | H30: =IF(Sabit_2026_08[[#This Row],[DOP]]="","",Sabit_2026_08[[#This Row],[DOP]]/$T$3) | M30: 46237 | N30: Remitly | O30: 1500 | P30: 58.4 | Q30: =IF(Transfer_2026_08[[#This Row],[USD]]="","",Transfer_2026_08[[#This Row],[USD]]*Transfer_2026_08[[#This Row],[Kur]]) -> 87600
M31: 46252 | N31: PayPal | O31: 300 | P31: 57.1 | Q31: =IF(Transfer_2026_08[[#This Row],[USD]]="","",Transfer_2026_08[[#This Row],[USD]]*Transfer_2026_08[[#This Row],[Kur]]) -> 17130
Q32: =IF(Transfer_2026_08[[#This Row],[USD]]="","",Transfer_2026_08[[#This Row],[USD]]*Transfer_2026_08[[#This Row],[Kur]])
Q33: =IF(Transfer_2026_08[[#This Row],[USD]]="","",Transfer_2026_08[[#This Row],[USD]]*Transfer_2026_08[[#This Row],[Kur]])
Q34: =IF(Transfer_2026_08[[#This Row],[USD]]="","",Transfer_2026_08[[#This Row],[USD]]*Transfer_2026_08[[#This Row],[Kur]])
B37: İşlem geçmişi | H37: =COUNT(Islem_2026_08[Tutar])&" işlem · toplam "&FIXED($T$5,2)&" DOP" -> 10 işlem · toplam 27,850.00 DOP
B38: Tarih | C38: Açıklama | D38: Yer | E38: Kategori | F38: Yöntem | G38: Tutar | H38: Para birimi | I38: DOP | J38: USD | K38: Notlar
B39: 46236 | C39: Weekly groceries | D39: Supermercado Nacional | E39: Market | F39: Kart | G39: 5230 | H39: DOP | I39: =IF(Islem_2026_08[[#This Row],[Tutar]]="","",IF(Islem_2026_08[[#This Row],[Para birimi]]="USD",Islem_2026_08[[#This Row],[Tutar]]*$T$3,Islem_2026_08[[#This Row],[Tutar]])) -> 5230 | J39: =IF(Islem_2026_08[[#This Row],[DOP]]="","",Islem_2026_08[[#This Row],[DOP]]/$T$3) -> 89.888284
B40: 46238 | C40: Uber | D40: Uber | E40: Ulaşım | F40: Kart | G40: 410 | H40: DOP | I40: =IF(Islem_2026_08[[#This Row],[Tutar]]="","",IF(Islem_2026_08[[#This Row],[Para birimi]]="USD",Islem_2026_08[[#This Row],[Tutar]]*$T$3,Islem_2026_08[[#This Row],[Tutar]])) -> 410 | J40: =IF(Islem_2026_08[[#This Row],[DOP]]="","",Islem_2026_08[[#This Row],[DOP]]/$T$3) -> 7.0466915
B41: 46240 | C41: Lunch | D41: Adrian Tropical | E41: Yemek | F41: Kart | G41: 1280 | H41: DOP | I41: =IF(Islem_2026_08[[#This Row],[Tutar]]="","",IF(Islem_2026_08[[#This Row],[Para birimi]]="USD",Islem_2026_08[[#This Row],[Tutar]]*$T$3,Islem_2026_08[[#This Row],[Tutar]])) -> 1280 | J41: =IF(Islem_2026_08[[#This Row],[DOP]]="","",Islem_2026_08[[#This Row],[DOP]]/$T$3) -> 21.999427
B42: 46243 | C42: Gas | D42: Texaco Churchill | E42: Ulaşım | F42: Kart | G42: 2200 | H42: DOP | I42: =IF(Islem_2026_08[[#This Row],[Tutar]]="","",IF(Islem_2026_08[[#This Row],[Para birimi]]="USD",Islem_2026_08[[#This Row],[Tutar]]*$T$3,Islem_2026_08[[#This Row],[Tutar]])) -> 2200 | J42: =IF(Islem_2026_08[[#This Row],[DOP]]="","",Islem_2026_08[[#This Row],[DOP]]/$T$3) -> 37.811515
B43: 46246 | C43: Concert | D43: Teatro Nacional | E43: Eğlence | F43: Banka uygulaması | G43: 2500 | H43: DOP | I43: =IF(Islem_2026_08[[#This Row],[Tutar]]="","",IF(Islem_2026_08[[#This Row],[Para birimi]]="USD",Islem_2026_08[[#This Row],[Tutar]]*$T$3,Islem_2026_08[[#This Row],[Tutar]])) -> 2500 | J43: =IF(Islem_2026_08[[#This Row],[DOP]]="","",Islem_2026_08[[#This Row],[DOP]]/$T$3) -> 42.967631
B44: 46249 | C44: Weekly groceries | D44: Jumbo | E44: Market | F44: Kart | G44: 4680 | H44: DOP | I44: =IF(Islem_2026_08[[#This Row],[Tutar]]="","",IF(Islem_2026_08[[#This Row],[Para birimi]]="USD",Islem_2026_08[[#This Row],[Tutar]]*$T$3,Islem_2026_08[[#This Row],[Tutar]])) -> 4680 | J44: =IF(Islem_2026_08[[#This Row],[DOP]]="","",Islem_2026_08[[#This Row],[DOP]]/$T$3) -> 80.435405
...

Sheet Eylül 2026
B1: FE Finance | D1: Eylül 2026 | M1: Ay kuru | N1: ="1 USD = "&FIXED($T$3,2)&" DOP" -> 1 USD = 58.57 DOP
B2: Yeni ay: sayfada ayı kapatıp Excel'i indirin veya bu sayfayı çoğaltın (sekmeye sağ tıklayın → Taşı veya Kopyala → Kopya oluştur). | T2: Hesaplamalar
T3: =IFERROR(SUMPRODUCT(Transfer_2026_09[USD],Transfer_2026_09[Kur])/SUM(Transfer_2026_09[USD]),Config!$C$4) -> 58.574348
B4: TOPLAM PARA | G4: KULLANILAN BÜTÇE | J4: =UPPER($D$1) -> EYLÜL 2026 | T4: =SUMIFS(Sabit_2026_09[DOP],Sabit_2026_09[Ödendi],"Evet") -> 42081.541
B5: =C8*$T$3+C9 -> 321654.83 | J5: ="Kullanılan bütçe: %"&FIXED(100*$T$8/MAX(1,O6),1) -> Kullanılan bütçe: %95.2 | T5: =SUM(Islem_2026_09[DOP]) -> 24555
B6: =C8+C9/$T$3 -> 5491.3941 | G6: ■ Ödenen sabitler | I6: =$T$4 -> 42081.541 | J6: Planlanan bütçe | O6: 70000 | T6: =SUMIFS(Sabit_2026_09[DOP],Sabit_2026_09[Ödendi],"Hayır") -> 0
T7: =MAX(0,O6-T4-T5-T6) -> 3363.4591
B8: ABD hesabı | C8: 4100 | D8: USD | G8: ■ İşlemler | I8: =$T$5 -> 24555 | J8: Bugüne kadar kullanılan | O8: =$T$8 -> 66636.541 | T8: =T4+T5 -> 66636.541
B9: DC hesabı | C9: 81500 | D9: DOP | G9: ■ Bekleyen sabitler | I9: =$T$6 -> 0 | J9: Kalan | O9: =O6-O8 -> 3363.4591 | T9: =FIXED(T8,0) -> 66,637
B10: Ayın geliri | C10: 5800 | D10: USD | G10: ■ Serbest | I10: =$T$7 -> 3363.4591 | J10: Bekleyen sabitlerden sonra kalan | O10: =O9-$T$6 -> 3363.4591 | T10: ="/ "&FIXED(O6,0)&" DOP" -> / 70,000 DOP
B11: Gelir − kullanılan | C11: =C10*$T$3-$T$8 -> 273094.68 | J11: USD olarak kullanılan | O11: =$T$8/$T$3 -> 1137.6403
B14: Aylık giderler | H14: =COUNTIFS(Sabit_2026_09[Ödendi],"Evet")&" / "&COUNTA(Sabit_2026_09[Kalem])&" ödendi · toplam "&FIXED(SUM(Sabit_2026_09[DOP]),2)&" DOP" -> 11 / 11 ödendi · toplam 42,081.54 DOP | M14: Kategoriye göre | Q14: DOP
B15: Ödendi | C15: Kalem | D15: Gün | E15: Tutar | F15: Para birimi | G15: DOP | H15: USD | M15: Sabit giderler | O15: =Q15 -> 42081.541 | Q15: =$T$4 -> 42081.541
B16: Evet | C16: Electricity | E16: 1412.8 | F16: DOP | G16: =IF(Sabit_2026_09[[#This Row],[Tutar]]="","",IF(Sabit_2026_09[[#This Row],[Para birimi]]="USD",Sabit_2026_09[[#This Row],[Tutar]]*$T$3,Sabit_2026_09[[#This Row],[Tutar]])) -> 1412.8 | H16: =IF(Sabit_2026_09[[#This Row],[DOP]]="","",Sabit_2026_09[[#This Row],[DOP]]/$T$3) -> 24.119773 | M16: Yemek | O16: =Q16 -> 1420 | Q16: =SUMIFS(Islem_2026_09[DOP],Islem_2026_09[Kategori],M16) -> 1420
B17: Evet | C17: Internet | E17: 2699 | F17: DOP | G17: =IF(Sabit_2026_09[[#This Row],[Tutar]]="","",IF(Sabit_2026_09[[#This Row],[Para birimi]]="USD",Sabit_2026_09[[#This Row],[Tutar]]*$T$3,Sabit_2026_09[[#This Row],[Tutar]])) -> 2699 | H17: =IF(Sabit_2026_09[[#This Row],[DOP]]="","",Sabit_2026_09[[#This Row],[DOP]]/$T$3) -> 46.078191 | M17: Market | O17: =Q17 -> 10295 | Q17: =SUMIFS(Islem_2026_09[DOP],Islem_2026_09[Kategori],M17) -> 10295
B18: Evet | C18: Health insurance | E18: 5640 | F18: DOP | G18: =IF(Sabit_2026_09[[#This Row],[Tutar]]="","",IF(Sabit_2026_09[[#This Row],[Para birimi]]="USD",Sabit_2026_09[[#This Row],[Tutar]]*$T$3,Sabit_2026_09[[#This Row],[Tutar]])) -> 5640 | H18: =IF(Sabit_2026_09[[#This Row],[DOP]]="","",Sabit_2026_09[[#This Row],[DOP]]/$T$3) -> 96.287884 | M18: Ulaşım | O18: =Q18 -> 4360 | Q18: =SUMIFS(Islem_2026_09[DOP],Islem_2026_09[Kategori],M18) -> 4360
B19: Evet | C19: Fridge payment | E19: 15000 | F19: DOP | G19: =IF(Sabit_2026_09[[#This Row],[Tutar]]="","",IF(Sabit_2026_09[[#This Row],[Para birimi]]="USD",Sabit_2026_09[[#This Row],[Tutar]]*$T$3,Sabit_2026_09[[#This Row],[Tutar]])) -> 15000 | H19: =IF(Sabit_2026_09[[#This Row],[DOP]]="","",Sabit_2026_09[[#This Row],[DOP]]/$T$3) -> 256.0848 | M19: Eğlence | O19: =Q19 -> 850 | Q19: =SUMIFS(Islem_2026_09[DOP],Islem_2026_09[Kategori],M19) -> 850
B20: Evet | C20: Claude | D20: 5 | E20: 106 | F20: USD | G20: =IF(Sabit_2026_09[[#This Row],[Tutar]]="","",IF(Sabit_2026_09[[#This Row],[Para birimi]]="USD",Sabit_2026_09[[#This Row],[Tutar]]*$T$3,Sabit_2026_09[[#This Row],[Tutar]])) -> 6208.8809 | H20: =IF(Sabit_2026_09[[#This Row],[DOP]]="","",Sabit_2026_09[[#This Row],[DOP]]/$T$3) -> 106 | M20: Sağlık | O20: =Q20 -> 980 | Q20: =SUMIFS(Islem_2026_09[DOP],Islem_2026_09[Kategori],M20) -> 980
B21: Evet | C21: Google One | D21: 16 | E21: 121.56 | F21: DOP | G21: =IF(Sabit_2026_09[[#This Row],[Tutar]]="","",IF(Sabit_2026_09[[#This Row],[Para birimi]]="USD",Sabit_2026_09[[#This Row],[Tutar]]*$T$3,Sabit_2026_09[[#This Row],[Tutar]])) -> 121.56 | H21: =IF(Sabit_2026_09[[#This Row],[DOP]]="","",Sabit_2026_09[[#This Row],[DOP]]/$T$3) -> 2.0753112 | M21: Giyim | O21: =Q21 -> 0 | Q21: =SUMIFS(Islem_2026_09[DOP],Islem_2026_09[Kategori],M21) -> 0
B22: Evet | C22: iCloud+ | D22: 17 | E22: 604 | F22: DOP | G22: =IF(Sabit_2026_09[[#This Row],[Tutar]]="","",IF(Sabit_2026_09[[#This Row],[Para birimi]]="USD",Sabit_2026_09[[#This Row],[Tutar]]*$T$3,Sabit_2026_09[[#This Row],[Tutar]])) -> 604 | H22: =IF(Sabit_2026_09[[#This Row],[DOP]]="","",Sabit_2026_09[[#This Row],[DOP]]/$T$3) -> 10.311681 | M22: Ev | O22: =Q22 -> 0 | Q22: =SUMIFS(Islem_2026_09[DOP],Islem_2026_09[Kategori],M22) -> 0
B23: Evet | C23: Cluely | E23: 308 | F23: DOP | G23: =IF(Sabit_2026_09[[#This Row],[Tutar]]="","",IF(Sabit_2026_09[[#This Row],[Para birimi]]="USD",Sabit_2026_09[[#This Row],[Tutar]]*$T$3,Sabit_2026_09[[#This Row],[Tutar]])) -> 308 | H23: =IF(Sabit_2026_09[[#This Row],[DOP]]="","",Sabit_2026_09[[#This Row],[DOP]]/$T$3) -> 5.2582745 | M23: Abonelikler | O23: =Q23 -> 0 | Q23: =SUMIFS(Islem_2026_09[DOP],Islem_2026_09[Kategori],M23) -> 0
B24: Evet | C24: Smartfit | D24: 17 | E24: 1550 | F24: DOP | G24: =IF(Sabit_2026_09[[#This Row],[Tutar]]="","",IF(Sabit_2026_09[[#This Row],[Para birimi]]="USD",Sabit_2026_09[[#This Row],[Tutar]]*$T$3,Sabit_2026_09[[#This Row],[Tutar]])) -> 1550 | H24: =IF(Sabit_2026_09[[#This Row],[DOP]]="","",Sabit_2026_09[[#This Row],[DOP]]/$T$3) -> 26.462096 | M24: Eğitim | O24: =Q24 -> 1850 | Q24: =SUMIFS(Islem_2026_09[DOP],Islem_2026_09[Kategori],M24) -> 1850
B25: Evet | C25: Netflix | E25: 1137.3 | F25: DOP | G25: =IF(Sabit_2026_09[[#This Row],[Tutar]]="","",IF(Sabit_2026_09[[#This Row],[Para birimi]]="USD",Sabit_2026_09[[#This Row],[Tutar]]*$T$3,Sabit_2026_09[[#This Row],[Tutar]])) -> 1137.3 | H25: =IF(Sabit_2026_09[[#This Row],[DOP]]="","",Sabit_2026_09[[#This Row],[DOP]]/$T$3) -> 19.416349 | M25: Seyahat | O25: =Q25 -> 4800 | Q25: =SUMIFS(Islem_2026_09[DOP],Islem_2026_09[Kategori],M25) -> 4800
B26: Evet | C26: Unicaribe | E26: 7400 | F26: DOP | G26: =IF(Sabit_2026_09[[#This Row],[Tutar]]="","",IF(Sabit_2026_09[[#This Row],[Para birimi]]="USD",Sabit_2026_09[[#This Row],[Tutar]]*$T$3,Sabit_2026_09[[#This Row],[Tutar]])) -> 7400 | H26: =IF(Sabit_2026_09[[#This Row],[DOP]]="","",Sabit_2026_09[[#This Row],[DOP]]/$T$3) -> 126.33517
G27: =IF(Sabit_2026_09[[#This Row],[Tutar]]="","",IF(Sabit_2026_09[[#This Row],[Para birimi]]="USD",Sabit_2026_09[[#This Row],[Tutar]]*$T$3,Sabit_2026_09[[#This Row],[Tutar]])) | H27: =IF(Sabit_2026_09[[#This Row],[DOP]]="","",Sabit_2026_09[[#This Row],[DOP]]/$T$3)
G28: =IF(Sabit_2026_09[[#This Row],[Tutar]]="","",IF(Sabit_2026_09[[#This Row],[Para birimi]]="USD",Sabit_2026_09[[#This Row],[Tutar]]*$T$3,Sabit_2026_09[[#This Row],[Tutar]])) | H28: =IF(Sabit_2026_09[[#This Row],[DOP]]="","",Sabit_2026_09[[#This Row],[DOP]]/$T$3) | M28: Transferler USD → DOP | O28: ="Ortalama "&FIXED($T$3,2) -> Ortalama 58.57
G29: =IF(Sabit_2026_09[[#This Row],[Tutar]]="","",IF(Sabit_2026_09[[#This Row],[Para birimi]]="USD",Sabit_2026_09[[#This Row],[Tutar]]*$T$3,Sabit_2026_09[[#This Row],[Tutar]])) | H29: =IF(Sabit_2026_09[[#This Row],[DOP]]="","",Sabit_2026_09[[#This Row],[DOP]]/$T$3) | M29: Tarih | N29: Kanal | O29: USD | P29: Kur | Q29: DOP
G30: =IF(Sabit_2026_09[[#This Row],[Tutar]]="","",IF(Sabit_2026_09[[#This Row],[Para birimi]]="USD",Sabit_2026_09[[#This Row],[Tutar]]*$T$3,Sabit_2026_09[[#This Row],[Tutar]])) | H30: =IF(Sabit_2026_09[[#This Row],[DOP]]="","",Sabit_2026_09[[#This Row],[DOP]]/$T$3) | M30: 46267 | N30: Remitly | O30: 1500 | P30: 58.55 | Q30: =IF(Transfer_2026_09[[#This Row],[USD]]="","",Transfer_2026_09[[#This Row],[USD]]*Transfer_2026_09[[#This Row],[Kur]]) -> 87825
M31: 46282 | N31: Remitly | O31: 800 | P31: 58.62 | Q31: =IF(Transfer_2026_09[[#This Row],[USD]]="","",Transfer_2026_09[[#This Row],[USD]]*Transfer_2026_09[[#This Row],[Kur]]) -> 46896
Q32: =IF(Transfer_2026_09[[#This Row],[USD]]="","",Transfer_2026_09[[#This Row],[USD]]*Transfer_2026_09[[#This Row],[Kur]])
Q33: =IF(Transfer_2026_09[[#This Row],[USD]]="","",Transfer_2026_09[[#This Row],[USD]]*Transfer_2026_09[[#This Row],[Kur]])
Q34: =IF(Transfer_2026_09[[#This Row],[USD]]="","",Transfer_2026_09[[#This Row],[USD]]*Transfer_2026_09[[#This Row],[Kur]])
B37: İşlem geçmişi | H37: =COUNT(Islem_2026_09[Tutar])&" işlem · toplam "&FIXED($T$5,2)&" DOP" -> 10 işlem · toplam 24,555.00 DOP
B38: Tarih | C38: Açıklama | D38: Yer | E38: Kategori | F38: Yöntem | G38: Tutar | H38: Para birimi | I38: DOP | J38: USD | K38: Notlar
B39: 46266 | C39: Weekly groceries | D39: Supermercado Bravo | E39: Market | F39: Kart | G39: 4975 | H39: DOP | I39: =IF(Islem_2026_09[[#This Row],[Tutar]]="","",IF(Islem_2026_09[[#This Row],[Para birimi]]="USD",Islem_2026_09[[#This Row],[Tutar]]*$T$3,Islem_2026_09[[#This Row],[Tutar]])) -> 4975 | J39: =IF(Islem_2026_09[[#This Row],[DOP]]="","",Islem_2026_09[[#This Row],[DOP]]/$T$3) -> 84.934791
B40: 46268 | C40: Accounting book | D40: Librería Cuesta | E40: Eğitim | F40: Kart | G40: 1850 | H40: DOP | I40: =IF(Islem_2026_09[[#This Row],[Tutar]]="","",IF(Islem_2026_09[[#This Row],[Para birimi]]="USD",Islem_2026_09[[#This Row],[Tutar]]*$T$3,Islem_2026_09[[#This Row],[Tutar]])) -> 1850 | J40: =IF(Islem_2026_09[[#This Row],[DOP]]="","",Islem_2026_09[[#This Row],[DOP]]/$T$3) -> 31.583792
B41: 46270 | C41: Uber | D41: Uber | E41: Ulaşım | F41: Kart | G41: 360 | H41: DOP | I41: =IF(Islem_2026_09[[#This Row],[Tutar]]="","",IF(Islem_2026_09[[#This Row],[Para birimi]]="USD",Islem_2026_09[[#This Row],[Tutar]]*$T$3,Islem_2026_09[[#This Row],[Tutar]])) -> 360 | J41: =IF(Islem_2026_09[[#This Row],[DOP]]="","",Islem_2026_09[[#This Row],[DOP]]/$T$3) -> 6.1460351
B42: 46273 | C42: Lunch | D42: El Conuco | E42: Yemek | F42: Kart | G42: 1420 | H42: DOP | I42: =IF(Islem_2026_09[[#This Row],[Tutar]]="","",IF(Islem_2026_09[[#This Row],[Para birimi]]="USD",Islem_2026_09[[#This Row],[Tutar]]*$T$3,Islem_2026_09[[#This Row],[Tutar]])) -> 1420 | J42: =IF(Islem_2026_09[[#This Row],[DOP]]="","",Islem_2026_09[[#This Row],[DOP]]/$T$3) -> 24.242694
B43: 46276 | C43: Gas | D43: Texaco | E43: Ulaşım | F43: Kart | G43: 2100 | H43: DOP | I43: =IF(Islem_2026_09[[#This Row],[Tutar]]="","",IF(Islem_2026_09[[#This Row],[Para birimi]]="USD",Islem_2026_09[[#This Row],[Tutar]]*$T$3,Islem_2026_09[[#This Row],[Tutar]])) -> 2100 | J43: =IF(Islem_2026_09[[#This Row],[DOP]]="","",Islem_2026_09[[#This Row],[DOP]]/$T$3) -> 35.851872
B44: 46279 | C44: Movies | D44: Caribbean Cinemas | E44: Eğlence | F44: Banka uygulaması | G44: 850 | H44: DOP | I44: =IF(Islem_2026_09[[#This Row],[Tutar]]="","",IF(Islem_2026_09[[#This Row],[Para birimi]]="USD",Islem_2026_09[[#This Row],[Tutar]]*$T$3,Islem_2026_09[[#This Row],[Tutar]])) -> 850 | J44: =IF(Islem_2026_09[[#This Row],[DOP]]="","",Islem_2026_09[[#This Row],[DOP]]/$T$3) -> 14.511472
...

Sheet Ekim 2026
B1: FE Finance | D1: Ekim 2026 | M1: Ay kuru | N1: ="1 USD = "&FIXED($T$3,2)&" DOP" -> 1 USD = 58.76 DOP
B2: Yeni ay: sayfada ayı kapatıp Excel'i indirin veya bu sayfayı çoğaltın (sekmeye sağ tıklayın → Taşı veya Kopyala → Kopya oluştur). | T2: Hesaplamalar
T3: =IFERROR(SUMPRODUCT(Transfer_2026_10[USD],Transfer_2026_10[Kur])/SUM(Transfer_2026_10[USD]),Config!$C$4) -> 58.76
B4: TOPLAM PARA | G4: KULLANILAN BÜTÇE | J4: =UPPER($D$1) -> EKIM 2026 | T4: =SUMIFS(Sabit_2026_10[DOP],Sabit_2026_10[Ödendi],"Evet") -> 38304.71
B5: =C8*$T$3+C9 -> 340243.2 | J5: ="Kullanılan bütçe: %"&FIXED(100*$T$8/MAX(1,O6),1) -> Kullanılan bütçe: %70.2 | T5: =SUM(Islem_2026_10[DOP]) -> 10845
B6: =C8+C9/$T$3 -> 5790.388 | G6: ■ Ödenen sabitler | I6: =$T$4 -> 38304.71 | J6: Planlanan bütçe | O6: 70000 | T6: =SUMIFS(Sabit_2026_10[DOP],Sabit_2026_10[Ödendi],"Hayır") -> 3720.86
T7: =MAX(0,O6-T4-T5-T6) -> 17129.43
B8: ABD hesabı | C8: 4320 | D8: USD | G8: ■ İşlemler | I8: =$T$5 -> 10845 | J8: Bugüne kadar kullanılan | O8: =$T$8 -> 49149.71 | T8: =T4+T5 -> 49149.71
B9: DC hesabı | C9: 86400 | D9: DOP | G9: ■ Bekleyen sabitler | I9: =$T$6 -> 3720.86 | J9: Kalan | O9: =O6-O8 -> 20850.29 | T9: =FIXED(T8,0) -> 49,150
B10: Ayın geliri | C10: 5800 | D10: USD | G10: ■ Serbest | I10: =$T$7 -> 17129.43 | J10: Bekleyen sabitlerden sonra kalan | O10: =O9-$T$6 -> 17129.43 | T10: ="/ "&FIXED(O6,0)&" DOP" -> / 70,000 DOP
B11: Gelir − kullanılan | C11: =C10*$T$3-$T$8 -> 291658.29 | J11: USD olarak kullanılan | O11: =$T$8/$T$3 -> 836.44843
B14: Aylık giderler | H14: =COUNTIFS(Sabit_2026_10[Ödendi],"Evet")&" / "&COUNTA(Sabit_2026_10[Kalem])&" ödendi · toplam "&FIXED(SUM(Sabit_2026_10[DOP]),2)&" DOP" -> 6 / 11 ödendi · toplam 42,025.57 DOP | M14: Kategoriye göre | Q14: DOP
B15: Ödendi | C15: Kalem | D15: Gün | E15: Tutar | F15: Para birimi | G15: DOP | H15: USD | M15: Sabit giderler | O15: =Q15 -> 38304.71 | Q15: =$T$4 -> 38304.71
B16: Evet | C16: Electricity | E16: 1337.15 | F16: DOP | G16: =IF(Sabit_2026_10[[#This Row],[Tutar]]="","",IF(Sabit_2026_10[[#This Row],[Para birimi]]="USD",Sabit_2026_10[[#This Row],[Tutar]]*$T$3,Sabit_2026_10[[#This Row],[Tutar]])) -> 1337.15 | H16: =IF(Sabit_2026_10[[#This Row],[DOP]]="","",Sabit_2026_10[[#This Row],[DOP]]/$T$3) -> 22.756127 | M16: Yemek | O16: =Q16 -> 1535 | Q16: =SUMIFS(Islem_2026_10[DOP],Islem_2026_10[Kategori],M16) -> 1535
B17: Evet | C17: Internet | E17: 2699 | F17: DOP | G17: =IF(Sabit_2026_10[[#This Row],[Tutar]]="","",IF(Sabit_2026_10[[#This Row],[Para birimi]]="USD",Sabit_2026_10[[#This Row],[Tutar]]*$T$3,Sabit_2026_10[[#This Row],[Tutar]])) -> 2699 | H17: =IF(Sabit_2026_10[[#This Row],[DOP]]="","",Sabit_2026_10[[#This Row],[DOP]]/$T$3) -> 45.932607 | M17: Market | O17: =Q17 -> 4850 | Q17: =SUMIFS(Islem_2026_10[DOP],Islem_2026_10[Kategori],M17) -> 4850
B18: Evet | C18: Health insurance | E18: 5640 | F18: DOP | G18: =IF(Sabit_2026_10[[#This Row],[Tutar]]="","",IF(Sabit_2026_10[[#This Row],[Para birimi]]="USD",Sabit_2026_10[[#This Row],[Tutar]]*$T$3,Sabit_2026_10[[#This Row],[Tutar]])) -> 5640 | H18: =IF(Sabit_2026_10[[#This Row],[DOP]]="","",Sabit_2026_10[[#This Row],[DOP]]/$T$3) -> 95.983662 | M18: Ulaşım | O18: =Q18 -> 2320 | Q18: =SUMIFS(Islem_2026_10[DOP],Islem_2026_10[Kategori],M18) -> 2320
B19: Evet | C19: Fridge payment | E19: 15000 | F19: DOP | G19: =IF(Sabit_2026_10[[#This Row],[Tutar]]="","",IF(Sabit_2026_10[[#This Row],[Para birimi]]="USD",Sabit_2026_10[[#This Row],[Tutar]]*$T$3,Sabit_2026_10[[#This Row],[Tutar]])) -> 15000 | H19: =IF(Sabit_2026_10[[#This Row],[DOP]]="","",Sabit_2026_10[[#This Row],[DOP]]/$T$3) -> 255.2757 | M19: Eğlence | O19: =Q19 -> 900 | Q19: =SUMIFS(Islem_2026_10[DOP],Islem_2026_10[Kategori],M19) -> 900
B20: Evet | C20: Claude | D20: 5 | E20: 106 | F20: USD | G20: =IF(Sabit_2026_10[[#This Row],[Tutar]]="","",IF(Sabit_2026_10[[#This Row],[Para birimi]]="USD",Sabit_2026_10[[#This Row],[Tutar]]*$T$3,Sabit_2026_10[[#This Row],[Tutar]])) -> 6228.56 | H20: =IF(Sabit_2026_10[[#This Row],[DOP]]="","",Sabit_2026_10[[#This Row],[DOP]]/$T$3) -> 106 | M20: Sağlık | O20: =Q20 -> 1240 | Q20: =SUMIFS(Islem_2026_10[DOP],Islem_2026_10[Kategori],M20) -> 1240
B21: Hayır | C21: Google One | D21: 16 | E21: 121.56 | F21: DOP | G21: =IF(Sabit_2026_10[[#This Row],[Tutar]]="","",IF(Sabit_2026_10[[#This Row],[Para birimi]]="USD",Sabit_2026_10[[#This Row],[Tutar]]*$T$3,Sabit_2026_10[[#This Row],[Tutar]])) -> 121.56 | H21: =IF(Sabit_2026_10[[#This Row],[DOP]]="","",Sabit_2026_10[[#This Row],[DOP]]/$T$3) -> 2.0687543 | M21: Giyim | O21: =Q21 -> 0 | Q21: =SUMIFS(Islem_2026_10[DOP],Islem_2026_10[Kategori],M21) -> 0
B22: Hayır | C22: iCloud+ | D22: 17 | E22: 604 | F22: DOP | G22: =IF(Sabit_2026_10[[#This Row],[Tutar]]="","",IF(Sabit_2026_10[[#This Row],[Para birimi]]="USD",Sabit_2026_10[[#This Row],[Tutar]]*$T$3,Sabit_2026_10[[#This Row],[Tutar]])) -> 604 | H22: =IF(Sabit_2026_10[[#This Row],[DOP]]="","",Sabit_2026_10[[#This Row],[DOP]]/$T$3) -> 10.279101 | M22: Ev | O22: =Q22 -> 0 | Q22: =SUMIFS(Islem_2026_10[DOP],Islem_2026_10[Kategori],M22) -> 0
B23: Hayır | C23: Cluely | E23: 308 | F23: DOP | G23: =IF(Sabit_2026_10[[#This Row],[Tutar]]="","",IF(Sabit_2026_10[[#This Row],[Para birimi]]="USD",Sabit_2026_10[[#This Row],[Tutar]]*$T$3,Sabit_2026_10[[#This Row],[Tutar]])) -> 308 | H23: =IF(Sabit_2026_10[[#This Row],[DOP]]="","",Sabit_2026_10[[#This Row],[DOP]]/$T$3) -> 5.241661 | M23: Abonelikler | O23: =Q23 -> 0 | Q23: =SUMIFS(Islem_2026_10[DOP],Islem_2026_10[Kategori],M23) -> 0
B24: Hayır | C24: Smartfit | D24: 17 | E24: 1550 | F24: DOP | G24: =IF(Sabit_2026_10[[#This Row],[Tutar]]="","",IF(Sabit_2026_10[[#This Row],[Para birimi]]="USD",Sabit_2026_10[[#This Row],[Tutar]]*$T$3,Sabit_2026_10[[#This Row],[Tutar]])) -> 1550 | H24: =IF(Sabit_2026_10[[#This Row],[DOP]]="","",Sabit_2026_10[[#This Row],[DOP]]/$T$3) -> 26.378489 | M24: Eğitim | O24: =Q24 -> 0 | Q24: =SUMIFS(Islem_2026_10[DOP],Islem_2026_10[Kategori],M24) -> 0
B25: Hayır | C25: Netflix | E25: 1137.3 | F25: DOP | G25: =IF(Sabit_2026_10[[#This Row],[Tutar]]="","",IF(Sabit_2026_10[[#This Row],[Para birimi]]="USD",Sabit_2026_10[[#This Row],[Tutar]]*$T$3,Sabit_2026_10[[#This Row],[Tutar]])) -> 1137.3 | H25: =IF(Sabit_2026_10[[#This Row],[DOP]]="","",Sabit_2026_10[[#This Row],[DOP]]/$T$3) -> 19.355003 | M25: Seyahat | O25: =Q25 -> 0 | Q25: =SUMIFS(Islem_2026_10[DOP],Islem_2026_10[Kategori],M25) -> 0
B26: Evet | C26: Unicaribe | E26: 7400 | F26: DOP | G26: =IF(Sabit_2026_10[[#This Row],[Tutar]]="","",IF(Sabit_2026_10[[#This Row],[Para birimi]]="USD",Sabit_2026_10[[#This Row],[Tutar]]*$T$3,Sabit_2026_10[[#This Row],[Tutar]])) -> 7400 | H26: =IF(Sabit_2026_10[[#This Row],[DOP]]="","",Sabit_2026_10[[#This Row],[DOP]]/$T$3) -> 125.93601
G27: =IF(Sabit_2026_10[[#This Row],[Tutar]]="","",IF(Sabit_2026_10[[#This Row],[Para birimi]]="USD",Sabit_2026_10[[#This Row],[Tutar]]*$T$3,Sabit_2026_10[[#This Row],[Tutar]])) | H27: =IF(Sabit_2026_10[[#This Row],[DOP]]="","",Sabit_2026_10[[#This Row],[DOP]]/$T$3)
G28: =IF(Sabit_2026_10[[#This Row],[Tutar]]="","",IF(Sabit_2026_10[[#This Row],[Para birimi]]="USD",Sabit_2026_10[[#This Row],[Tutar]]*$T$3,Sabit_2026_10[[#This Row],[Tutar]])) | H28: =IF(Sabit_2026_10[[#This Row],[DOP]]="","",Sabit_2026_10[[#This Row],[DOP]]/$T$3) | M28: Transferler USD → DOP | O28: ="Ortalama "&FIXED($T$3,2) -> Ortalama 58.76
G29: =IF(Sabit_2026_10[[#This Row],[Tutar]]="","",IF(Sabit_2026_10[[#This Row],[Para birimi]]="USD",Sabit_2026_10[[#This Row],[Tutar]]*$T$3,Sabit_2026_10[[#This Row],[Tutar]])) | H29: =IF(Sabit_2026_10[[#This Row],[DOP]]="","",Sabit_2026_10[[#This Row],[DOP]]/$T$3) | M29: Tarih | N29: Kanal | O29: USD | P29: Kur | Q29: DOP
G30: =IF(Sabit_2026_10[[#This Row],[Tutar]]="","",IF(Sabit_2026_10[[#This Row],[Para birimi]]="USD",Sabit_2026_10[[#This Row],[Tutar]]*$T$3,Sabit_2026_10[[#This Row],[Tutar]])) | H30: =IF(Sabit_2026_10[[#This Row],[DOP]]="","",Sabit_2026_10[[#This Row],[DOP]]/$T$3) | M30: 46297 | N30: Remitly | O30: 1500 | P30: 58.76 | Q30: =IF(Transfer_2026_10[[#This Row],[USD]]="","",Transfer_2026_10[[#This Row],[USD]]*Transfer_2026_10[[#This Row],[Kur]]) -> 88140
Q31: =IF(Transfer_2026_10[[#This Row],[USD]]="","",Transfer_2026_10[[#This Row],[USD]]*Transfer_2026_10[[#This Row],[Kur]])
Q32: =IF(Transfer_2026_10[[#This Row],[USD]]="","",Transfer_2026_10[[#This Row],[USD]]*Transfer_2026_10[[#This Row],[Kur]])
Q33: =IF(Transfer_2026_10[[#This Row],[USD]]="","",Transfer_2026_10[[#This Row],[USD]]*Transfer_2026_10[[#This Row],[Kur]])
Q34: =IF(Transfer_2026_10[[#This Row],[USD]]="","",Transfer_2026_10[[#This Row],[USD]]*Transfer_2026_10[[#This Row],[Kur]])
B37: İşlem geçmişi | H37: =COUNT(Islem_2026_10[Tutar])&" işlem · toplam "&FIXED($T$5,2)&" DOP" -> 7 işlem · toplam 10,845.00 DOP
B38: Tarih | C38: Açıklama | D38: Yer | E38: Kategori | F38: Yöntem | G38: Tutar | H38: Para birimi | I38: DOP | J38: USD | K38: Notlar
B39: 46296 | C39: Weekly groceries | D39: Supermercado Nacional | E39: Market | F39: Kart | G39: 4850 | H39: DOP | I39: =IF(Islem_2026_10[[#This Row],[Tutar]]="","",IF(Islem_2026_10[[#This Row],[Para birimi]]="USD",Islem_2026_10[[#This Row],[Tutar]]*$T$3,Islem_2026_10[[#This Row],[Tutar]])) -> 4850 | J39: =IF(Islem_2026_10[[#This Row],[DOP]]="","",Islem_2026_10[[#This Row],[DOP]]/$T$3) -> 82.539142
B40: 46297 | C40: Uber to work | D40: Uber | E40: Ulaşım | F40: Kart | G40: 320 | H40: DOP | I40: =IF(Islem_2026_10[[#This Row],[Tutar]]="","",IF(Islem_2026_10[[#This Row],[Para birimi]]="USD",Islem_2026_10[[#This Row],[Tutar]]*$T$3,Islem_2026_10[[#This Row],[Tutar]])) -> 320 | J40: =IF(Islem_2026_10[[#This Row],[DOP]]="","",Islem_2026_10[[#This Row],[DOP]]/$T$3) -> 5.4458816
B41: 46298 | C41: Lunch | D41: Adrian Tropical | E41: Yemek | F41: Kart | G41: 1150 | H41: DOP | I41: =IF(Islem_2026_10[[#This Row],[Tutar]]="","",IF(Islem_2026_10[[#This Row],[Para birimi]]="USD",Islem_2026_10[[#This Row],[Tutar]]*$T$3,Islem_2026_10[[#This Row],[Tutar]])) -> 1150 | J41: =IF(Islem_2026_10[[#This Row],[DOP]]="","",Islem_2026_10[[#This Row],[DOP]]/$T$3) -> 19.571137
B42: 46299 | C42: Movies | D42: Caribbean Cinemas | E42: Eğlence | F42: Banka uygulaması | G42: 900 | H42: DOP | I42: =IF(Islem_2026_10[[#This Row],[Tutar]]="","",IF(Islem_2026_10[[#This Row],[Para birimi]]="USD",Islem_2026_10[[#This Row],[Tutar]]*$T$3,Islem_2026_10[[#This Row],[Tutar]])) -> 900 | J42: =IF(Islem_2026_10[[#This Row],[DOP]]="","",Islem_2026_10[[#This Row],[DOP]]/$T$3) -> 15.316542
B43: 46300 | C43: Pharmacy | D43: Farmacia Carol | E43: Sağlık | F43: Kart | G43: 1240 | H43: DOP | I43: =IF(Islem_2026_10[[#This Row],[Tutar]]="","",IF(Islem_2026_10[[#This Row],[Para birimi]]="USD",Islem_2026_10[[#This Row],[Tutar]]*$T$3,Islem_2026_10[[#This Row],[Tutar]])) -> 1240 | J43: =IF(Islem_2026_10[[#This Row],[DOP]]="","",Islem_2026_10[[#This Row],[DOP]]/$T$3) -> 21.102791
B44: 46301 | C44: Gas | D44: Texaco | E44: Ulaşım | F44: Kart | G44: 2000 | H44: DOP | I44: =IF(Islem_2026_10[[#This Row],[Tutar]]="","",IF(Islem_2026_10[[#This Row],[Para birimi]]="USD",Islem_2026_10[[#This Row],[Tutar]]*$T$3,Islem_2026_10[[#This Row],[Tutar]])) -> 2000 | J44: =IF(Islem_2026_10[[#This Row],[DOP]]="","",Islem_2026_10[[#This Row],[DOP]]/$T$3) -> 34.03676
...

Sheet Birikimler
B1: FE Finance | D1: Birikimler
R2: Hesaplamalar
B3: BU AY | C3: TOPLAM PARA (DOP) | F3: BÜTÇE | I3: KULLANILAN | K3: KALAN | N3: KUR | R3: =IFERROR(INDIRECT("'"&Config!$C$5&"'!T3"),Config!$C$4) -> 58.76
B4: =Config!$C$5 -> Ekim 2026 | C4: =IFERROR(INDIRECT("'"&Config!$C$5&"'!B5"),"") -> 340243.2 | F4: =IFERROR(INDIRECT("'"&Config!$C$5&"'!O6"),"") -> 70000 | I4: =IFERROR(INDIRECT("'"&Config!$C$5&"'!T8"),"") -> 49149.71 | K4: =IFERROR(INDIRECT("'"&Config!$C$5&"'!O9"),"") -> 20850.29 | N4: =IFERROR(INDIRECT("'"&Config!$C$5&"'!T3"),Config!$C$4) -> 58.76 | R4: =J12*((YEAR(N12)-YEAR(L12))*12+MONTH(N12)-MONTH(L12)+1) -> 45000
R5: =SUMIFS(Katkilar[USD],Katkilar[Hedef],"Trip to Turkey") -> 142.55446
B6: Emergency fund | E6: Fondo de emergencia | I6: Trip to Turkey | L6: =FIXED(J12,0)&" USD / ay" -> 3,000 USD / ay | R6: =MAX(1,(YEAR(N12)-YEAR(TODAY()))*12+MONTH(N12)-MONTH(TODAY())+1-IF(COUNTIFS(Katkilar[Hedef],"Trip to Turkey",Katkilar[Ay],Config!$C$5)>0,1,0)) -> 12
B7: Değişken katkılar | E7: Değişken katkılar | I7: ="Kalan "&$R$6&" katkı · hedef için ayda "&FIXED($R$7,0)&" USD" -> Kalan 12 katkı · hedef için ayda 3,738 USD | R7: =MAX(0,R4-R5)/R6 -> 3738.1205
B8: =SUMIFS(Katkilar[USD],Katkilar[Hedef],"Emergency fund") -> 143.57148 | E8: =SUMIFS(Katkilar[USD],Katkilar[Hedef],"Fondo de emergencia") -> 144.5885 | I8: =$R$5 -> 142.55446 | L8: =$R$5*$R$3 -> 8376.5 | R8: =IF(R4=0,0,R5/R4) -> 0.0031678769
B9: =B8*$R$3 -> 8436.26 | E9: =E8*$R$3 -> 8496.02
I10: =$R$8 -> 0.0031678769
B11: =COUNTIFS(Katkilar[Hedef],"Emergency fund")&" katkı kaydedildi" -> 2 katkı kaydedildi | E11: =COUNTIFS(Katkilar[Hedef],"Fondo de emergencia")&" katkı kaydedildi" -> 2 katkı kaydedildi | I11: ="%"&FIXED(100*$R$8,0)&" / "&FIXED($R$4,0)&" USD" -> %0 / 45,000 USD | L11: ="Hedef: "&PROPER(CHOOSE(MONTH(N12),"Ocak","Şubat","Mart","Nisan","Mayıs","Haziran","Temmuz","Ağustos","Eylül","Ekim","Kasım","Aralık"))&" "&YEAR(N12) -> Hedef: Ekim 2027
I12: Aylık | J12: 3000 | K12: Başlangıç | L12: 46235 | M12: Bitiş | N12: 46661 | R12: =J20*((YEAR(N20)-YEAR(L20))*12+MONTH(N20)-MONTH(L20)+1) -> 2703
R13: =SUMIFS(Katkilar[USD],Katkilar[Hedef],"Car") -> 146.62253
B14: Gifts | I14: Car | L14: =FIXED(J20,0)&" USD / ay" -> 451 USD / ay | R14: =MAX(1,(YEAR(N20)-YEAR(TODAY()))*12+MONTH(N20)-MONTH(TODAY())+1-IF(COUNTIFS(Katkilar[Hedef],"Car",Katkilar[Ay],Config!$C$5)>0,1,0)) -> 1
B15: Değişken katkılar | I15: ="Kalan "&$R$14&" katkı · hedef için ayda "&FIXED($R$15,0)&" USD" -> Kalan 1 katkı · hedef için ayda 2,556 USD | R15: =MAX(0,R12-R13)/R14 -> 2556.3775
B16: =SUMIFS(Katkilar[USD],Katkilar[Hedef],"Gifts") -> 145.60551 | I16: =$R$13 -> 146.62253 | L16: =$R$13*$R$3 -> 8615.54 | R16: =IF(R12=0,0,R13/R12) -> 0.05424437
B17: =B16*$R$3 -> 8555.78
I18: =$R$16 -> 0.05424437
B19: =COUNTIFS(Katkilar[Hedef],"Gifts")&" katkı kaydedildi" -> 2 katkı kaydedildi | I19: ="%"&FIXED(100*$R$16,0)&" / "&FIXED($R$12,0)&" USD" -> %5 / 2,703 USD | L19: ="Hedef: "&PROPER(CHOOSE(MONTH(N20),"Ocak","Şubat","Mart","Nisan","Mayıs","Haziran","Temmuz","Ağustos","Eylül","Ekim","Kasım","Aralık"))&" "&YEAR(N20) -> Hedef: Haziran 2026
I20: Aylık | J20: 450.5 | K20: Başlangıç | L20: 46023 | M20: Bitiş | N20: 46174 | R20: =J28*((YEAR(N28)-YEAR(L28))*12+MONTH(N28)-MONTH(L28)+1) -> 73200
R21: =SUMIFS(Katkilar[USD],Katkilar[Hedef],"House") -> 147.63955
B22: Düğün & balayı | I22: House | L22: =FIXED(J28,0)&" USD / ay" -> 1,200 USD / ay | R22: =MAX(1,(YEAR(N28)-YEAR(TODAY()))*12+MONTH(N28)-MONTH(TODAY())+1-IF(COUNTIFS(Katkilar[Hedef],"House",Katkilar[Ay],Config!$C$5)>0,1,0)) -> 50
B23: Değişken katkılar | I23: ="Kalan "&$R$22&" katkı · hedef için ayda "&FIXED($R$23,0)&" USD" -> Kalan 50 katkı · hedef için ayda 1,461 USD | R23: =MAX(0,R20-R21)/R22 -> 1461.0472
B24: =SUMIFS(Katkilar[USD],Katkilar[Hedef],"Düğün & balayı") -> 148.65657 | I24: =$R$21 -> 147.63955 | L24: =$R$21*$R$3 -> 8675.3 | R24: =IF(R20=0,0,R21/R20) -> 0.0020169338
B25: =B24*$R$3 -> 8735.06
I26: =$R$24 -> 0.0020169338
B27: =COUNTIFS(Katkilar[Hedef],"Düğün & balayı")&" katkı kaydedildi" -> 2 katkı kaydedildi | I27: ="%"&FIXED(100*$R$24,0)&" / "&FIXED($R$20,0)&" USD" -> %0 / 73,200 USD | L27: ="Hedef: "&PROPER(CHOOSE(MONTH(N28),"Ocak","Şubat","Mart","Nisan","Mayıs","Haziran","Temmuz","Ağustos","Eylül","Ekim","Kasım","Aralık"))&" "&YEAR(N28) -> Hedef: Aralık 2030
I28: Aylık | J28: 1200 | K28: Başlangıç | L28: 45992 | M28: Bitiş | N28: 47818 | R28: =J36*((YEAR(N36)-YEAR(L36))*12+MONTH(N36)-MONTH(L36)+1) -> 900
R29: =SUMIFS(Katkilar[USD],Katkilar[Hedef],"Ahorro personal") -> 149.67359
I30: Ahorro personal | L30: =FIXED(J36,0)&" USD / ay" -> 75 USD / ay | R30: =MAX(1,(YEAR(N36)-YEAR(TODAY()))*12+MONTH(N36)-MONTH(TODAY())+1-IF(COUNTIFS(Katkilar[Hedef],"Ahorro personal",Katkilar[Ay],Config!$C$5)>0,1,0)) -> 14
I31: ="Kalan "&$R$30&" katkı · hedef için ayda "&FIXED($R$31,0)&" USD" -> Kalan 14 katkı · hedef için ayda 54 USD | R31: =MAX(0,R28-R29)/R30 -> 53.594744
I32: =$R$29 -> 149.67359 | L32: =$R$29*$R$3 -> 8794.82 | R32: =IF(R28=0,0,R29/R28) -> 0.16630399
I34: =$R$32 -> 0.16630399
I35: ="%"&FIXED(100*$R$32,0)&" / "&FIXED($R$28,0)&" USD" -> %17 / 900 USD | L35: ="Hedef: "&PROPER(CHOOSE(MONTH(N36),"Ocak","Şubat","Mart","Nisan","Mayıs","Haziran","Temmuz","Ağustos","Eylül","Ekim","Kasım","Aralık"))&" "&YEAR(N36) -> Hedef: Aralık 2027
I36: Aylık | J36: 75 | K36: Başlangıç | L36: 46388 | M36: Bitiş | N36: 46722
B38: Aylara göre gelir | I38: Katkılar | L38: ="Toplam "&FIXED(SUM(Katkilar[USD]),2)&" USD" -> Toplam 1,319.60 USD
B39: Ay | C39: Gelir USD | D39: Kur | E39: Gelir DOP | F39: Biriken USD | G39: Birikim % | I39: Tarih | J39: Ay | K39: Hedef | L39: Tutar | M39: Para birimi | N39: USD | O39: DOP
B40: Ağustos 2026 | C40: =IFERROR(INDIRECT("'"&B40&"'!C10"),"") -> 5800 | D40: =IFERROR(INDIRECT("'"&B40&"'!T3"),"") -> 58.183333 | E40: =IF(C40="","",C40*D40) -> 337463.33 | F40: =IF(C40="","",SUMIFS(Katkilar[USD],Katkilar[Ay],B40)) -> 936 | G40: =IF(OR(C40="",C40=0),"",F40/C40) -> 0.16137931 | I40: 46235 | J40: =IF(Katkilar[[#This Row],[Tarih]]="","",CHOOSE(MONTH(Katkilar[[#This Row],[Tarih]]),"Ocak","Şubat","Mart","Nisan","Mayıs","Haziran","Temmuz","Ağustos","Eylül","Ekim","Kasım","Aralık")&" "&YEAR(Katkilar[[#This Row],[Tarih]])) -> Ağustos 2026 | K40: Trip to Turkey | L40: 100 | M40: USD | N40: =IF(Katkilar[[#This Row],[Tutar]]="","",IF(Katkilar[[#This Row],[Para birimi]]="USD",Katkilar[[#This Row],[Tutar]],Katkilar[[#This Row],[Tutar]]/IFERROR(INDIRECT("'"&Katkilar[[#This Row],[Ay]]&"'!T3"),Config!$C$4))) -> 100 | O40: =IF(Katkilar[[#This Row],[USD]]="","",Katkilar[[#This Row],[USD]]*IFERROR(INDIRECT("'"&Katkilar[[#This Row],[Ay]]&"'!T3"),Config!$C$4)) -> 5818.3333
B41: Eylül 2026 | C41: =IFERROR(INDIRECT("'"&B41&"'!C10"),"") -> 5800 | D41: =IFERROR(INDIRECT("'"&B41&"'!T3"),"") -> 58.574348 | E41: =IF(C41="","",C41*D41) -> 339731.22 | F41: =IF(C41="","",SUMIFS(Katkilar[USD],Katkilar[Ay],B41)) -> 0 | G41: =IF(OR(C41="",C41=0),"",F41/C41) -> 0 | I41: 46236 | J41: =IF(Katkilar[[#This Row],[Tarih]]="","",CHOOSE(MONTH(Katkilar[[#This Row],[Tarih]]),"Ocak","Şubat","Mart","Nisan","Mayıs","Haziran","Temmuz","Ağustos","Eylül","Ekim","Kasım","Aralık")&" "&YEAR(Katkilar[[#This Row],[Tarih]])) -> Ağustos 2026 | K41: Emergency fund | L41: 101 | M41: USD | N41: =IF(Katkilar[[#This Row],[Tutar]]="","",IF(Katkilar[[#This Row],[Para birimi]]="USD",Katkilar[[#This Row],[Tutar]],Katkilar[[#This Row],[Tutar]]/IFERROR(INDIRECT("'"&Katkilar[[#This Row],[Ay]]&"'!T3"),Config!$C$4))) -> 101 | O41: =IF(Katkilar[[#This Row],[USD]]="","",Katkilar[[#This Row],[USD]]*IFERROR(INDIRECT("'"&Katkilar[[#This Row],[Ay]]&"'!T3"),Config!$C$4)) -> 5876.5167
B42: Ekim 2026 | C42: =IFERROR(INDIRECT("'"&B42&"'!C10"),"") -> 5800 | D42: =IFERROR(INDIRECT("'"&B42&"'!T3"),"") -> 58.76 | E42: =IF(C42="","",C42*D42) -> 340808 | F42: =IF(C42="","",SUMIFS(Katkilar[USD],Katkilar[Ay],B42)) -> 383.60279 | G42: =IF(OR(C42="",C42=0),"",F42/C42) -> 0.066138412 | I42: 46237 | J42: =IF(Katkilar[[#This Row],[Tarih]]="","",CHOOSE(MONTH(Katkilar[[#This Row],[Tarih]]),"Ocak","Şubat","Mart","Nisan","Mayıs","Haziran","Temmuz","Ağustos","Eylül","Ekim","Kasım","Aralık")&" "&YEAR(Katkilar[[#This Row],[Tarih]])) -> Ağustos 2026 | K42: Fondo de emergencia | L42: 102 | M42: USD | N42: =IF(Katkilar[[#This Row],[Tutar]]="","",IF(Katkilar[[#This Row],[Para birimi]]="USD",Katkilar[[#This Row],[Tutar]],Katkilar[[#This Row],[Tutar]]/IFERROR(INDIRECT("'"&Katkilar[[#This Row],[Ay]]&"'!T3"),Config!$C$4))) -> 102 | O42: =IF(Katkilar[[#This Row],[USD]]="","",Katkilar[[#This Row],[USD]]*IFERROR(INDIRECT("'"&Katkilar[[#This Row],[Ay]]&"'!T3"),Config!$C$4)) -> 5934.7
...

Sheet Config
B1: Yapılandırma
B3: AYARLAR | E3: KATEGORİLER | F3: ÖDEME YÖNTEMLERİ | G3: BİRİKİM HEDEFLERİ
B4: Varsayılan kur (transfersiz ay) | C4: 58.76 | E4: Yemek | F4: Kart | G4: Trip to Turkey
B5: Bu ay (Birikimler'de gösterilir) | C5: Ekim 2026 | E5: Market | F5: Havale | G5: Emergency fund
E6: Ulaşım | F6: Banka uygulaması | G6: Fondo de emergencia
E7: Eğlence | G7: Gifts
E8: Sağlık | G8: Car
E9: Giyim | G9: House
E10: Ev | G10: Düğün & balayı
E11: Abonelikler | G11: Ahorro personal
E12: Eğitim
E13: Seyahat
